Workbook

Sheet 件番
A2: no. | B2: 件番 | C2: 件名 | D2: 管理者
A3: 0 | B3: 2032B1007 | C3: 関東交技会議（支店、生産
B4: 2032B1011 | C4: 関東交技講習・研修・試験
B5: 2032B1000 | C5: 関東交技年休
A6: 97 | C6: MT等
A7: 99 | B7: 2032B1008 | C7: 関東交通整備
A8: 98 | B8: 2032B9900 | C8: コロナ対応
A9: 96 | B9: 1000F1012 | C9: 本社e-Learning | D9: 本社講習･研修･試験
A10: 1 | B10: H6420399B | C10: 随）R3アクア渋滞対策 | D10: 堤慎司
A11: 2 | B11: H6420412A | C11: 随）外環工事影響検討 | D11: 堤慎司
A12: 3 | B12: H64206880 | C12: 随）R3横浜新道資料作成 | D12: 堤慎司
A13: 4 | B13: H6420508B | C13: 随）Ｒ３上瀬谷交通アセス | D13: 堤慎司
A14: 5 | B14: H6420437A | C14: P）Ｒ３特殊車両適正化 | D14: 菊池省二
A15: 6 | B15: H65200820 | C15: Ｐ）特車通行取締調査 | D15: 後藤秀典
A16: 7 | B16: H6420396A | C16: Ｐ）Ｒ３常陸交通安全検討 | D16: 堤慎司
A17: 8 | B17: H6470031B | C17: 簡Ｐ）広国交通事故調査 | D17: 林祐志
A18: 9 | B18: H6520259A | C18: Ｐ）Ｒ４東京国道事故対策 | D18: 林祐志
A19: 10 | B19: H6420416A | C19: Ｐ）R3横浜国道事故対策 | D19: 林祐志
A20: 11 | B20: H6570031B | C20: 簡Ｐ）R4広国事故調査検討 | D20: 林祐志
... A24: 15 | B24: H65202000 | C24: Ｐ）交通危険分析 | D24: 後藤秀典
A25: 16 | C25: Ｐ）R4横浜国道事故対策 | D25: 林祐志
A26: 17 | B26: H6520304B | C26: 随）R4上瀬谷公園アセス | D26: 林祐志
A27: 18 | B27: H6520234B | C27: 随）R4旧深谷準備書作成 | D27: 林祐志
A28: 19 | B28: H65204850 | C28: 随）外環三郷西ＩＣ渋滞 | D28: 大坪裕哉
A29: 20
A30: 21 | B30: H65205220 | C30: アクア照明効果分析 | D30: 林祐志
A31: 22 | B31: H6620007B | C31: R4アクア渋滞対策交通検討 | D31: 大坪裕哉
A32: 23 | B32: H65202900 | C32: 随）R4NEE自動運転 | D32: 後藤秀典
A33: 24 | B33: H65204610 | C33: 休憩施設利用動向調査業務 | D33: 林祐志
A34: 25 | C34: エンジ見積もりMT | D34: 大坪裕哉
A35: 26 | B35: H6620235A | C35: Ｐ）Ｒ５東京国道事故対策 | D35: 林祐志
A36: 27 | B36: H66202880 | C36: 価）入間高架橋交通運用 | D36: 大坪裕哉
A37: 28 | B37: H66203940 | C37: Ｐ）Ｒ５生活道路安全対策 | D37: 林祐志
A38: 29 | B38: H66204050 | C38: 随）休憩施設利用調査 | D38: 林祐志
A39: 30 | B39: H66204160 | C39: 価）上野原IC渋滞調査 | D39: 大坪裕哉
A40: 31 | B40: H6650095A | C40: 簡P)R5沼津河国交通事故対 | D40: 大坪裕哉
A41: 32 | B41: H67203230 | C41: 随）東京外環工事車線運用 | D41: 大坪裕哉
A42: 33 | B42: H6720329B | C42: K）京葉道花輪IC渋滞対策 | D42: 柏祐樹
A43: 34 | B43: H6720360A | C43: Ｐ）Ｒ6東京国道事故対策 | D43: 林祐志
A44: 35 | B44: H6720389A | C44: Ｐ）Ｒ６横国交通事故対策 | D44: 林祐志
...

Sheet 3月
B2: No. （件番SheetのNo.を入力⇒） | S2: 99
B3: 件番（自動入力） | D3: =IF(ISERROR(VLOOKUP(D2,件番!$A$10:$D$113,2,FALSE)),"",(VLOOKUP(D2,件番!$A$10:$D$113,2,FALSE))) | E3: =IF(ISERROR(VLOOKUP(E2,件番!$A$10:$D$113,2,FALSE)),"",(VLOOKUP(E2,件番!$A$10:$D$113,2,FALSE))) | F3: =IF(ISERROR(VLOOKUP(F2,件番!$A$10:$D$113,2,FALSE)),"",(VLOOKUP(F2,件番!$A$10:$D$113,2,FALSE))) | G3: =IF(ISERROR(VLOOKUP(G2,件番!$A$10:$D$113,2,FALSE)),"",(VLOOKUP(G2,件番!$A$10:$D$113,2,FALSE))) | H3: =IF(ISERROR(VLOOKUP(H2,件番!$A$10:$D$113,2,FALSE)),"",(VLOOKUP(H2,件番!$A$10:$D$113,2,FALSE))) | I3: =IF(ISERROR(VLOOKUP(I2,件番!$A$10:$D$113,2,FALSE)),"",(VLOOKUP(I2,件番!$A$10:$D$113,2,FALSE))) | J3: =IF(ISERROR(VLOOKUP(J2,件番!$A$10:$D$113,2,FALSE)),"",(VLOOKUP(J2,件番!$A$10:$D$113,2,FALSE))) | K3: =IF(ISERROR(VLOOKUP(K2,件番!$A$10:$D$113,2,FALSE)),"",(VLOOKUP(K2,件番!$A$10:$D$113,2,FALSE))) | ... O3: =IF(ISERROR(VLOOKUP(O2,件番!$A$10:$D$113,2,FALSE)),"",(VLOOKUP(O2,件番!$A$10:$D$113,2,FALSE))) | S3: =IF(ISERROR(VLOOKUP(S2,件番!$A$3:$D$113,2,FALSE)),"",(VLOOKUP(S2,件番!$A$3:$D$113,2,FALSE))) -> 2032B1008
B4: 件名（自動入力） | D4: =IF(ISERROR(VLOOKUP(D2,件番!$A$10:$D$113,2,FALSE)),"",(VLOOKUP(D2,件番!$A$10:$D$113,3,FALSE))) | E4: =IF(ISERROR(VLOOKUP(E2,件番!$A$10:$D$113,2,FALSE)),"",(VLOOKUP(E2,件番!$A$10:$D$113,3,FALSE))) | F4: =IF(ISERROR(VLOOKUP(F2,件番!$A$10:$D$113,2,FALSE)),"",(VLOOKUP(F2,件番!$A$10:$D$113,3,FALSE))) | G4: =IF(ISERROR(VLOOKUP(G2,件番!$A$10:$D$113,2,FALSE)),"",(VLOOKUP(G2,件番!$A$10:$D$113,3,FALSE))) | H4: =IF(ISERROR(VLOOKUP(H2,件番!$A$10:$D$113,2,FALSE)),"",(VLOOKUP(H2,件番!$A$10:$D$113,3,FALSE))) | I4: =IF(ISERROR(VLOOKUP(I2,件番!$A$10:$D$113,2,FALSE)),"",(VLOOKUP(I2,件番!$A$10:$D$113,3,FALSE))) | J4: =IF(ISERROR(VLOOKUP(J2,件番!$A$10:$D$113,2,FALSE)),"",(VLOOKUP(J2,件番!$A$10:$D$113,3,FALSE))) | K4: =IF(ISERROR(VLOOKUP(K2,件番!$A$10:$D$113,2,FALSE)),"",(VLOOKUP(K2,件番!$A$10:$D$113,3,FALSE))) | ... O4: =IF(ISERROR(VLOOKUP(O2,件番!$A$10:$D$113,2,FALSE)),"",(VLOOKUP(O2,件番!$A$10:$D$113,3,FALSE))) | S4: =IF(ISERROR(VLOOKUP(S2,件番!$A$3:$D$113,2,FALSE)),"",(VLOOKUP(S2,件番!$A$3:$D$113,3,FALSE))) -> 関東交通整備
B5: 管理（自動入力） | D5: =IF(ISERROR(VLOOKUP(D2,件番!$A$10:$D$113,2,FALSE)),"",(VLOOKUP(D2,件番!$A$10:$D$113,4,FALSE))) | E5: =IF(ISERROR(VLOOKUP(E2,件番!$A$10:$D$113,2,FALSE)),"",(VLOOKUP(E2,件番!$A$10:$D$113,4,FALSE))) | F5: =IF(ISERROR(VLOOKUP(F2,件番!$A$10:$D$113,2,FALSE)),"",(VLOOKUP(F2,件番!$A$10:$D$113,4,FALSE))) | G5: =IF(ISERROR(VLOOKUP(G2,件番!$A$10:$D$113,2,FALSE)),"",(VLOOKUP(G2,件番!$A$10:$D$113,4,FALSE))) | H5: =IF(ISERROR(VLOOKUP(H2,件番!$A$10:$D$113,2,FALSE)),"",(VLOOKUP(H2,件番!$A$10:$D$113,4,FALSE))) | I5: =IF(ISERROR(VLOOKUP(I2,件番!$A$10:$D$113,2,FALSE)),"",(VLOOKUP(I2,件番!$A$10:$D$113,4,FALSE))) | J5: =IF(ISERROR(VLOOKUP(J2,件番!$A$10:$D$113,2,FALSE)),"",(VLOOKUP(J2,件番!$A$10:$D$113,4,FALSE))) | K5: =IF(ISERROR(VLOOKUP(K2,件番!$A$10:$D$113,2,FALSE)),"",(VLOOKUP(K2,件番!$A$10:$D$113,4,FALSE))) | ... O5: =IF(ISERROR(VLOOKUP(O2,件番!$A$10:$D$113,2,FALSE)),"",(VLOOKUP(O2,件番!$A$10:$D$113,4,FALSE))) | S5: =IF(ISERROR(VLOOKUP(S2,件番!$A$3:$D$113,2,FALSE)),"",(VLOOKUP(S2,件番!$A$3:$D$113,4,FALSE))) -> 0 | T5: 合計 | U5: 備考 | V5: 始業 | W5: 終業 | X5: 休憩 | Y5: 就業時間 | Z5: チェック
B6: 46082 | C6: =TEXT(B6,"aaa") -> 日 | T6: =SUM(D6:S6) -> 0 | Y6: =(W6-V6-X6)*24 -> 0 | Z6: =Y6-T6 -> 0
B7: 46083 | C7: =TEXT(B7,"aaa") -> 月 | T7: =SUM(D7:S7) -> 0 | V7: 0.375 | W7: 0.72916667 | X7: 0.052083333 | Y7: =(W7-V7-X7)*24 -> 7.25 | Z7: =Y7-T7 -> 7.25 | AA7: =AC7-AB7 -> 0 | AB7: 7.25 | AC7: =ABS(Y7) -> 7.25
B8: 46084 | C8: =TEXT(B8,"aaa") -> 火 | T8: =SUM(D8:S8) -> 0 | V8: 0.375 | W8: 0.72916667 | X8: 0.052083333 | Y8: =(W8-V8-X8)*24 -> 7.25 | Z8: =Y8-T8 -> 7.25 | AA8: =AC8-AB8 -> 0 | AB8: 7.25 | AC8: =ABS(Y8) -> 7.25
B9: 46085 | C9: =TEXT(B9,"aaa") -> 水 | T9: =SUM(D9:S9) -> 0 | V9: 0.375 | W9: 0.72916667 | X9: 0.052083333 | Y9: =(W9-V9-X9)*24 -> 7.25 | Z9: =Y9-T9 -> 7.25 | AA9: =AC9-AB9 -> 0 | AB9: 7.25 | AC9: =ABS(Y9) -> 7.25
B10: 46086 | C10: =TEXT(B10,"aaa") -> 木 | T10: =SUM(D10:S10) -> 0 | V10: 0.375 | W10: 0.72916667 | X10: 0.052083333 | Y10: =(W10-V10-X10)*24 -> 7.25 | Z10: =Y10-T10 -> 7.25 | AA10: =AC10-AB10 -> 0 | AB10: 7.25 | AC10: =ABS(Y10) -> 7.25
B11: 46087 | C11: =TEXT(B11,"aaa") -> 金 | T11: =SUM(D11:S11) -> 0 | V11: 0.375 | W11: 0.72916667 | X11: 0.052083333 | Y11: =(W11-V11-X11)*24 -> 7.25 | Z11: =Y11-T11 -> 7.25 | AA11: =AC11-AB11 -> 0 | AB11: 7.25 | AC11: =ABS(Y11) -> 7.25
B12: 46088 | C12: =TEXT(B12,"aaa") -> 土 | T12: =SUM(D12:S12) -> 0 | Y12: =(W12-V12-X12)*24 -> 0 | Z12: =Y12-T12 -> 0
B13: 46089 | C13: =TEXT(B13,"aaa") -> 日 | T13: =SUM(D13:S13) -> 0 | Y13: =(W13-V13-X13)*24 -> 0 | Z13: =Y13-T13 -> 0
B14: 46090 | C14: =TEXT(B14,"aaa") -> 月 | T14: =SUM(D14:S14) -> 0 | V14: 0.375 | W14: 0.72916667 | X14: 0.052083333 | Y14: =(W14-V14-X14)*24 -> 7.25 | Z14: =Y14-T14 -> 7.25 | AA14: =AC14-AB14 -> 0 | AB14: 7.25 | AC14: =ABS(Y14) -> 7.25
B15: 46091 | C15: =TEXT(B15,"aaa") -> 火 | T15: =SUM(D15:S15) -> 0 | V15: 0.375 | W15: 0.72916667 | X15: 0.052083333 | Y15: =(W15-V15-X15)*24 -> 7.25 | Z15: =Y15-T15 -> 7.25 | AA15: =AC15-AB15 -> 0 | AB15: 7.25 | AC15: =ABS(Y15) -> 7.25
B16: 46092 | C16: =TEXT(B16,"aaa") -> 水 | T16: =SUM(D16:S16) -> 0 | V16: 0.375 | W16: 0.72916667 | X16: 0.052083333 | Y16: =(W16-V16-X16)*24 -> 7.25 | Z16: =Y16-T16 -> 7.25 | AA16: =AC16-AB16 -> 0 | AB16: 7.25 | AC16: =ABS(Y16) -> 7.25
B17: 46093 | C17: =TEXT(B17,"aaa") -> 木 | T17: =SUM(D17:S17) -> 0 | V17: 0.375 | W17: 0.72916667 | X17: 0.052083333 | Y17: =(W17-V17-X17)*24 -> 7.25 | Z17: =Y17-T17 -> 7.25 | AA17: =AC17-AB17 -> 0 | AB17: 7.25 | AC17: =ABS(Y17) -> 7.25
B18: 46094 | C18: =TEXT(B18,"aaa") -> 金 | T18: =SUM(D18:S18) -> 0 | V18: 0.375 | W18: 0.72916667 | X18: 0.052083333 | Y18: =(W18-V18-X18)*24 -> 7.25 | Z18: =Y18-T18 -> 7.25 | AA18: =AC18-AB18 -> 0 | AB18: 7.25 | AC18: =ABS(Y18) -> 7.25
B19: 46095 | C19: =TEXT(B19,"aaa") -> 土 | T19: =SUM(D19:S19) -> 0 | Y19: =(W19-V19-X19)*24 -> 0 | Z19: =Y19-T19 -> 0
B20: 46096 | C20: =TEXT(B20,"aaa") -> 日 | T20: =SUM(D20:S20) -> 0 | Y20: =(W20-V20-X20)*24 -> 0 | Z20: =Y20-T20 -> 0
B21: 46097 | C21: =TEXT(B21,"aaa") -> 月 | T21: =SUM(D21:S21) -> 0 | V21: 0.375 | W21: 0.72916667 | X21: 0.052083333 | Y21: =(W21-V21-X21)*24 -> 7.25 | Z21: =Y21-T21 -> 7.25 | AA21: =AC21-AB21 -> 0 | AB21: 7.25 | AC21: =ABS(Y21) -> 7.25
B22: 46098 | C22: =TEXT(B22,"aaa") -> 火 | T22: =SUM(D22:S22) -> 0 | V22: 0.375 | W22: 0.72916667 | X22: 0.052083333 | Y22: =(W22-V22-X22)*24 -> 7.25 | Z22: =Y22-T22 -> 7.25 | AA22: =AC22-AB22 -> 0 | AB22: 7.25 | AC22: =ABS(Y22) -> 7.25
B23: 46099 | C23: =TEXT(B23,"aaa") -> 水 | T23: =SUM(D23:S23) -> 0 | V23: 0.375 | W23: 0.72916667 | X23: 0.052083333 | Y23: =(W23-V23-X23)*24 -> 7.25 | Z23: =Y23-T23 -> 7.25 | AA23: =AC23-AB23 -> 0 | AB23: 7.25 | AC23: =ABS(Y23) -> 7.25
B24: 46100 | C24: =TEXT(B24,"aaa") -> 木 | T24: =SUM(D24:S24) -> 0 | V24: 0.375 | W24: 0.72916667 | X24: 0.052083333 | Y24: =(W24-V24-X24)*24 -> 7.25 | Z24: =Y24-T24 -> 7.25 | AA24: =AC24-AB24 -> 0 | AB24: 7.25 | AC24: =ABS(Y24) -> 7.25
B25: 46101 | C25: =TEXT(B25,"aaa") -> 金 | T25: =SUM(D25:S25) -> 0 | U25: 春分の日 | Y25: =(W25-V25-X25)*24 -> 0 | Z25: =Y25-T25 -> 0
B26: 46102 | C26: =TEXT(B26,"aaa") -> 土 | T26: =SUM(D26:S26) -> 0 | Y26: =(W26-V26-X26)*24 -> 0 | Z26: =Y26-T26 -> 0
B27: 46103 | C27: =TEXT(B27,"aaa") -> 日 | T27: =SUM(D27:S27) -> 0 | Y27: =(W27-V27-X27)*24 -> 0 | Z27: =Y27-T27 -> 0
B28: 46104 | C28: =TEXT(B28,"aaa") -> 月 | T28: =SUM(D28:S28) -> 0 | V28: 0.375 | W28: 0.72916667 | X28: 0.052083333 | Y28: =(W28-V28-X28)*24 -> 7.25 | Z28: =Y28-T28 -> 7.25 | AA28: =AC28-AB28 -> 0 | AB28: 7.25 | AC28: =ABS(Y28) -> 7.25
B29: 46105 | C29: =TEXT(B29,"aaa") -> 火 | T29: =SUM(D29:S29) -> 0 | V29: 0.375 | W29: 0.72916667 | X29: 0.052083333 | Y29: =(W29-V29-X29)*24 -> 7.25 | Z29: =Y29-T29 -> 7.25 | AA29: =AC29-AB29 -> 0 | AB29: 7.25 | AC29: =ABS(Y29) -> 7.25
B30: 46106 | C30: =TEXT(B30,"aaa") -> 水 | T30: =SUM(D30:S30) -> 0 | V30: 0.375 | W30: 0.72916667 | X30: 0.052083333 | Y30: =(W30-V30-X30)*24 -> 7.25 | Z30: =Y30-T30 -> 7.25 | AA30: =AC30-AB30 -> 0 | AB30: 7.25 | AC30: =ABS(Y30) -> 7.25
B31: 46107 | C31: =TEXT(B31,"aaa") -> 木 | T31: =SUM(D31:S31) -> 0 | V31: 0.375 | W31: 0.72916667 | X31: 0.052083333 | Y31: =(W31-V31-X31)*24 -> 7.25 | Z31: =Y31-T31 -> 7.25 | AA31: =AC31-AB31 -> 0 | AB31: 7.25 | AC31: =ABS(Y31) -> 7.25
B32: 46108 | C32: =TEXT(B32,"aaa") -> 金 | T32: =SUM(D32:S32) -> 0 | V32: 0.375 | W32: 0.72916667 | X32: 0.052083333 | Y32: =(W32-V32-X32)*24 -> 7.25 | Z32: =Y32-T32 -> 7.25 | AA32: =AC32-AB32 -> 0 | AB32: 7.25 | AC32: =ABS(Y32) -> 7.25
B33: 46109 | C33: =TEXT(B33,"aaa") -> 土 | T33: =SUM(D33:S33) -> 0 | Y33: =(W33-V33-X33)*24 -> 0 | Z33: =Y33-T33 -> 0
B34: 46110 | C34: =TEXT(B34,"aaa") -> 日 | T34: =SUM(D34:S34) -> 0 | Y34: =(W34-V34-X34)*24 -> 0 | Z34: =Y34-T34 -> 0
B35: 46111 | C35: =TEXT(B35,"aaa") -> 月 | T35: =SUM(D35:S35) -> 0 | V35: 0.375 | W35: 0.72916667 | X35: 0.052083333 | Y35: =(W35-V35-X35)*24 -> 7.25 | Z35: =Y35-T35 -> 7.25 | AA35: =AC35-AB35 -> 0 | AB35: 7.25 | AC35: =ABS(Y35) -> 7.25
B36: 46112 | C36: =TEXT(B36,"aaa") -> 火 | T36: =SUM(D36:S36) -> 0 | V36: 0.375 | W36: 0.72916667 | X36: 0.052083333 | Y36: =(W36-V36-X36)*24 -> 7.25 | Z36: =Y36-T36 -> 7.25 | AA36: =AC36-AB36 -> 0 | AB36: 7.25 | AC36: =ABS(Y36) -> 7.25
B37: 月 | C37: 合計 | D37: =SUM(D6:D36) -> 0 | E37: =SUM(E6:E36) -> 0 | F37: =SUM(F6:F36) -> 0 | G37: =SUM(G6:G36) -> 0 | H37: =SUM(H6:H36) -> 0 | I37: =SUM(I6:I36) -> 0 | J37: =SUM(J6:J36) -> 0 | K37: =SUM(K6:K36) -> 0 | ... T37: =SUM(T6:T36) -> 0 | AA37: =SUM(AA6:AA36) -> 0 | AB37: =SUM(AB6:AB36) -> 152.25
B40: 直接経費（交通費等） | T40: 合計（円） | U40: 備考
C41: =TEXT(B41,"aaa") -> 土 | T41: =SUM(D41:S41) -> 0
C42: =TEXT(B42,"aaa") -> 土 | T42: =SUM(D42:S42) -> 0
C43: =TEXT(B43,"aaa") -> 土 | T43: =SUM(D43:S43) -> 0
...

Sheet 4月
B2: No. （件番SheetのNo.を入力⇒） | S2: 0
B3: 件番（自動入力） | D3: =IF(ISERROR(VLOOKUP(D2,件番!$A$10:$D$113,2,FALSE)),"",(VLOOKUP(D2,件番!$A$10:$D$113,2,FALSE))) | E3: =IF(ISERROR(VLOOKUP(E2,件番!$A$10:$D$113,2,FALSE)),"",(VLOOKUP(E2,件番!$A$10:$D$113,2,FALSE))) | F3: =IF(ISERROR(VLOOKUP(F2,件番!$A$10:$D$113,2,FALSE)),"",(VLOOKUP(F2,件番!$A$10:$D$113,2,FALSE))) | G3: =IF(ISERROR(VLOOKUP(G2,件番!$A$10:$D$113,2,FALSE)),"",(VLOOKUP(G2,件番!$A$10:$D$113,2,FALSE))) | H3: =IF(ISERROR(VLOOKUP(H2,件番!$A$10:$D$113,2,FALSE)),"",(VLOOKUP(H2,件番!$A$10:$D$113,2,FALSE))) | I3: =IF(ISERROR(VLOOKUP(I2,件番!$A$10:$D$113,2,FALSE)),"",(VLOOKUP(I2,件番!$A$10:$D$113,2,FALSE))) | J3: =IF(ISERROR(VLOOKUP(J2,件番!$A$10:$D$113,2,FALSE)),"",(VLOOKUP(J2,件番!$A$10:$D$113,2,FALSE))) | K3: =IF(ISERROR(VLOOKUP(K2,件番!$A$10:$D$113,2,FALSE)),"",(VLOOKUP(K2,件番!$A$10:$D$113,2,FALSE))) | ... N3: =IF(ISERROR(VLOOKUP(N2,件番!$A$10:$D$113,2,FALSE)),"",(VLOOKUP(N2,件番!$A$10:$D$113,2,FALSE))) | Q3: =IF(ISERROR(VLOOKUP(Q2,件番!$A$10:$D$113,2,FALSE)),"",(VLOOKUP(Q2,件番!$A$10:$D$113,2,FALSE))) | R3: =IF(ISERROR(VLOOKUP(R2,件番!$A$10:$D$113,2,FALSE)),"",(VLOOKUP(R2,件番!$A$10:$D$113,2,FALSE))) | S3: =IF(ISERROR(VLOOKUP(S2,件番!$A$3:$D$113,2,FALSE)),"",(VLOOKUP(S2,件番!$A$3:$D$113,2,FALSE))) -> 2032B1007
B4: 件名（自動入力） | D4: =IF(ISERROR(VLOOKUP(D2,件番!$A$10:$D$113,2,FALSE)),"",(VLOOKUP(D2,件番!$A$10:$D$113,3,FALSE))) | E4: =IF(ISERROR(VLOOKUP(E2,件番!$A$10:$D$113,2,FALSE)),"",(VLOOKUP(E2,件番!$A$10:$D$113,3,FALSE))) | F4: =IF(ISERROR(VLOOKUP(F2,件番!$A$10:$D$113,2,FALSE)),"",(VLOOKUP(F2,件番!$A$10:$D$113,3,FALSE))) | G4: =IF(ISERROR(VLOOKUP(G2,件番!$A$10:$D$113,2,FALSE)),"",(VLOOKUP(G2,件番!$A$10:$D$113,3,FALSE))) | H4: =IF(ISERROR(VLOOKUP(H2,件番!$A$10:$D$113,2,FALSE)),"",(VLOOKUP(H2,件番!$A$10:$D$113,3,FALSE))) | I4: =IF(ISERROR(VLOOKUP(I2,件番!$A$10:$D$113,2,FALSE)),"",(VLOOKUP(I2,件番!$A$10:$D$113,3,FALSE))) | J4: =IF(ISERROR(VLOOKUP(J2,件番!$A$10:$D$113,2,FALSE)),"",(VLOOKUP(J2,件番!$A$10:$D$113,3,FALSE))) | K4: =IF(ISERROR(VLOOKUP(K2,件番!$A$10:$D$113,2,FALSE)),"",(VLOOKUP(K2,件番!$A$10:$D$113,3,FALSE))) | ... N4: =IF(ISERROR(VLOOKUP(N2,件番!$A$10:$D$113,2,FALSE)),"",(VLOOKUP(N2,件番!$A$10:$D$113,3,FALSE))) | Q4: =IF(ISERROR(VLOOKUP(Q2,件番!$A$10:$D$113,2,FALSE)),"",(VLOOKUP(Q2,件番!$A$10:$D$113,3,FALSE))) | R4: =IF(ISERROR(VLOOKUP(R2,件番!$A$10:$D$113,2,FALSE)),"",(VLOOKUP(R2,件番!$A$10:$D$113,3,FALSE))) | S4: =IF(ISERROR(VLOOKUP(S2,件番!$A$3:$D$113,2,FALSE)),"",(VLOOKUP(S2,件番!$A$3:$D$113,3,FALSE))) -> 関東交技会議（支店、生産
B5: 管理（自動入力） | D5: =IF(ISERROR(VLOOKUP(D2,件番!$A$10:$D$113,2,FALSE)),"",(VLOOKUP(D2,件番!$A$10:$D$113,4,FALSE))) | E5: =IF(ISERROR(VLOOKUP(E2,件番!$A$10:$D$113,2,FALSE)),"",(VLOOKUP(E2,件番!$A$10:$D$113,4,FALSE))) | F5: =IF(ISERROR(VLOOKUP(F2,件番!$A$10:$D$113,2,FALSE)),"",(VLOOKUP(F2,件番!$A$10:$D$113,4,FALSE))) | G5: =IF(ISERROR(VLOOKUP(G2,件番!$A$10:$D$113,2,FALSE)),"",(VLOOKUP(G2,件番!$A$10:$D$113,4,FALSE))) | H5: =IF(ISERROR(VLOOKUP(H2,件番!$A$10:$D$113,2,FALSE)),"",(VLOOKUP(H2,件番!$A$10:$D$113,4,FALSE))) | I5: =IF(ISERROR(VLOOKUP(I2,件番!$A$10:$D$113,2,FALSE)),"",(VLOOKUP(I2,件番!$A$10:$D$113,4,FALSE))) | J5: =IF(ISERROR(VLOOKUP(J2,件番!$A$10:$D$113,2,FALSE)),"",(VLOOKUP(J2,件番!$A$10:$D$113,4,FALSE))) | K5: =IF(ISERROR(VLOOKUP(K2,件番!$A$10:$D$113,2,FALSE)),"",(VLOOKUP(K2,件番!$A$10:$D$113,4,FALSE))) | ... N5: =IF(ISERROR(VLOOKUP(N2,件番!$A$10:$D$113,2,FALSE)),"",(VLOOKUP(N2,件番!$A$10:$D$113,4,FALSE))) | Q5: =IF(ISERROR(VLOOKUP(Q2,件番!$A$10:$D$113,2,FALSE)),"",(VLOOKUP(Q2,件番!$A$10:$D$113,4,FALSE))) | R5: =IF(ISERROR(VLOOKUP(R2,件番!$A$10:$D$113,2,FALSE)),"",(VLOOKUP(R2,件番!$A$10:$D$113,4,FALSE))) | S5: =IF(ISERROR(VLOOKUP(S2,件番!$A$3:$D$113,2,FALSE)),"",(VLOOKUP(S2,件番!$A$3:$D$113,4,FALSE))) -> 0 | T5: 合計 | U5: 備考 | V5: 始業 | W5: 終業 | X5: 休憩 | Y5: 就業時間 | Z5: チェック
B6: 46113 | C6: =TEXT(B6,"aaa") -> 水 | T6: =SUM(D6:S6) -> 0 | V6: 0.375 | W6: 0.72916667 | X6: 0.052083333 | Y6: =(W6-V6-X6)*24 -> 7.25 | Z6: =Y6-T6 -> 7.25 | AA6: =AC6-AB6 -> 0 | AB6: 7.25 | AC6: =ABS(Y6) -> 7.25
B7: 46114 | C7: =TEXT(B7,"aaa") -> 木 | T7: =SUM(D7:S7) -> 0 | V7: 0.375 | W7: 0.72916667 | X7: 0.052083333 | Y7: =(W7-V7-X7)*24 -> 7.25 | Z7: =Y7-T7 -> 7.25 | AA7: =AC7-AB7 -> 0 | AB7: 7.25 | AC7: =ABS(Y7) -> 7.25
B8: 46115 | C8: =TEXT(B8,"aaa") -> 金 | T8: =SUM(D8:S8) -> 0 | V8: 0.375 | W8: 0.72916667 | X8: 0.052083333 | Y8: =(W8-V8-X8)*24 -> 7.25 | Z8: =Y8-T8 -> 7.25 | AA8: =AC8-AB8 -> 0 | AB8: 7.25 | AC8: =ABS(Y8) -> 7.25
B9: 46116 | C9: =TEXT(B9,"aaa") -> 土 | T9: =SUM(D9:S9) -> 0 | Y9: =(W9-V9-X9)*24 -> 0 | Z9: =Y9-T9 -> 0
B10: 46117 | C10: =TEXT(B10,"aaa") -> 日 | T10: =SUM(D10:S10) -> 0 | Y10: =(W10-V10-X10)*24 -> 0 | Z10: =Y10-T10 -> 0
B11: 46118 | C11: =TEXT(B11,"aaa") -> 月 | T11: =SUM(D11:S11) -> 0 | V11: 0.375 | W11: 0.72916667 | X11: 0.052083333 | Y11: =(W11-V11-X11)*24 -> 7.25 | Z11: =Y11-T11 -> 7.25 | AA11: =AC11-AB11 -> 0 | AB11: 7.25 | AC11: =ABS(Y11) -> 7.25
B12: 46119 | C12: =TEXT(B12,"aaa") -> 火 | T12: =SUM(D12:S12) -> 0 | V12: 0.375 | W12: 0.72916667 | X12: 0.052083333 | Y12: =(W12-V12-X12)*24 -> 7.25 | Z12: =Y12-T12 -> 7.25 | AA12: =AC12-AB12 -> 0 | AB12: 7.25 | AC12: =ABS(Y12) -> 7.25
B13: 46120 | C13: =TEXT(B13,"aaa") -> 水 | T13: =SUM(D13:S13) -> 0 | V13: 0.375 | W13: 0.72916667 | X13: 0.052083333 | Y13: =(W13-V13-X13)*24 -> 7.25 | Z13: =Y13-T13 -> 7.25 | AA13: =AC13-AB13 -> 0 | AB13: 7.25 | AC13: =ABS(Y13) -> 7.25
B14: 46121 | C14: =TEXT(B14,"aaa") -> 木 | T14: =SUM(D14:S14) -> 0 | V14: 0.375 | W14: 0.72916667 | X14: 0.052083333 | Y14: =(W14-V14-X14)*24 -> 7.25 | Z14: =Y14-T14 -> 7.25 | AA14: =AC14-AB14 -> 0 | AB14: 7.25 | AC14: =ABS(Y14) -> 7.25
B15: 46122 | C15: =TEXT(B15,"aaa") -> 金 | T15: =SUM(D15:S15) -> 0 | V15: 0.375 | W15: 0.72916667 | X15: 0.052083333 | Y15: =(W15-V15-X15)*24 -> 7.25 | Z15: =Y15-T15 -> 7.25 | AA15: =AC15-AB15 -> 0 | AB15: 7.25 | AC15: =ABS(Y15) -> 7.25
B16: 46123 | C16: =TEXT(B16,"aaa") -> 土 | T16: =SUM(D16:S16) -> 0 | Y16: =(W16-V16-X16)*24 -> 0 | Z16: =Y16-T16 -> 0
B17: 46124 | C17: =TEXT(B17,"aaa") -> 日 | T17: =SUM(D17:S17) -> 0 | Y17: =(W17-V17-X17)*24 -> 0 | Z17: =Y17-T17 -> 0
B18: 46125 | C18: =TEXT(B18,"aaa") -> 月 | T18: =SUM(D18:S18) -> 0 | V18: 0.375 | W18: 0.72916667 | X18: 0.052083333 | Y18: =(W18-V18-X18)*24 -> 7.25 | Z18: =Y18-T18 -> 7.25 | AA18: =AC18-AB18 -> 0 | AB18: 7.25 | AC18: =ABS(Y18) -> 7.25
B19: 46126 | C19: =TEXT(B19,"aaa") -> 火 | T19: =SUM(D19:S19) -> 0 | V19: 0.375 | W19: 0.72916667 | X19: 0.052083333 | Y19: =(W19-V19-X19)*24 -> 7.25 | Z19: =Y19-T19 -> 7.25 | AA19: =AC19-AB19 -> 0 | AB19: 7.25 | AC19: =ABS(Y19) -> 7.25
B20: 46127 | C20: =TEXT(B20,"aaa") -> 水 | T20: =SUM(D20:S20) -> 0 | V20: 0.375 | W20: 0.72916667 | X20: 0.052083333 | Y20: =(W20-V20-X20)*24 -> 7.25 | Z20: =Y20-T20 -> 7.25 | AA20: =AC20-AB20 -> 0 | AB20: 7.25 | AC20: =ABS(Y20) -> 7.25
B21: 46128 | C21: =TEXT(B21,"aaa") -> 木 | T21: =SUM(D21:S21) -> 0 | V21: 0.375 | W21: 0.72916667 | X21: 0.052083333 | Y21: =(W21-V21-X21)*24 -> 7.25 | Z21: =Y21-T21 -> 7.25 | AA21: =AC21-AB21 -> 0 | AB21: 7.25 | AC21: =ABS(Y21) -> 7.25
B22: 46129 | C22: =TEXT(B22,"aaa") -> 金 | T22: =SUM(D22:S22) -> 0 | V22: 0.375 | W22: 0.72916667 | X22: 0.052083333 | Y22: =(W22-V22-X22)*24 -> 7.25 | Z22: =Y22-T22 -> 7.25 | AA22: =AC22-AB22 -> 0 | AB22: 7.25 | AC22: =ABS(Y22) -> 7.25
B23: 46130 | C23: =TEXT(B23,"aaa") -> 土 | T23: =SUM(D23:S23) -> 0 | Y23: =(W23-V23-X23)*24 -> 0 | Z23: =Y23-T23 -> 0
B24: 46131 | C24: =TEXT(B24,"aaa") -> 日 | T24: =SUM(D24:S24) -> 0 | Y24: =(W24-V24-X24)*24 -> 0 | Z24: =Y24-T24 -> 0
B25: 46132 | C25: =TEXT(B25,"aaa") -> 月 | T25: =SUM(D25:S25) -> 0 | V25: 0.375 | W25: 0.72916667 | X25: 0.052083333 | Y25: =(W25-V25-X25)*24 -> 7.25 | Z25: =Y25-T25 -> 7.25 | AA25: =AC25-AB25 -> 0 | AB25: 7.25 | AC25: =ABS(Y25) -> 7.25
B26: 46133 | C26: =TEXT(B26,"aaa") -> 火 | T26: =SUM(D26:S26) -> 0 | V26: 0.375 | W26: 0.72916667 | X26: 0.052083333 | Y26: =(W26-V26-X26)*24 -> 7.25 | Z26: =Y26-T26 -> 7.25 | AA26: =AC26-AB26 -> 0 | AB26: 7.25 | AC26: =ABS(Y26) -> 7.25
B27: 46134 | C27: =TEXT(B27,"aaa") -> 水 | T27: =SUM(D27:S27) -> 0 | V27: 0.375 | W27: 0.72916667 | X27: 0.052083333 | Y27: =(W27-V27-X27)*24 -> 7.25 | Z27: =Y27-T27 -> 7.25 | AA27: =AC27-AB27 -> 0 | AB27: 7.25 | AC27: =ABS(Y27) -> 7.25
B28: 46135 | C28: =TEXT(B28,"aaa") -> 木 | T28: =SUM(D28:S28) -> 0 | V28: 0.375 | W28: 0.72916667 | X28: 0.052083333 | Y28: =(W28-V28-X28)*24 -> 7.25 | Z28: =Y28-T28 -> 7.25 | AA28: =AC28-AB28 -> 0 | AB28: 7.25 | AC28: =ABS(Y28) -> 7.25
B29: 46136 | C29: =TEXT(B29,"aaa") -> 金 | T29: =SUM(D29:S29) -> 0 | V29: 0.375 | W29: 0.72916667 | X29: 0.052083333 | Y29: =(W29-V29-X29)*24 -> 7.25 | Z29: =Y29-T29 -> 7.25 | AA29: =AC29-AB29 -> 0 | AB29: 7.25 | AC29: =ABS(Y29) -> 7.25
B30: 46137 | C30: =TEXT(B30,"aaa") -> 土 | T30: =SUM(D30:S30) -> 0 | Y30: =(W30-V30-X30)*24 -> 0 | Z30: =Y30-T30 -> 0
B31: 46138 | C31: =TEXT(B31,"aaa") -> 日 | T31: =SUM(D31:S31) -> 0 | Y31: =(W31-V31-X31)*24 -> 0 | Z31: =Y31-T31 -> 0
B32: 46139 | C32: =TEXT(B32,"aaa") -> 月 | T32: =SUM(D32:S32) -> 0 | V32: 0.375 | W32: 0.72916667 | X32: 0.052083333 | Y32: =(W32-V32-X32)*24 -> 7.25 | Z32: =Y32-T32 -> 7.25 | AA32: =AC32-AB32 -> 0 | AB32: 7.25 | AC32: =ABS(Y32) -> 7.25
B33: 46140 | C33: =TEXT(B33,"aaa") -> 火 | T33: =SUM(D33:S33) -> 0 | V33: 0.375 | W33: 0.72916667 | X33: 0.052083333 | Y33: =(W33-V33-X33)*24 -> 7.25 | Z33: =Y33-T33 -> 7.25 | AA33: =AC33-AB33 -> 0 | AB33: 7.25 | AC33: =ABS(Y33) -> 7.25
B34: 46141 | C34: =TEXT(B34,"aaa") -> 水 | T34: =SUM(D34:S34) -> 0 | U34: 昭和の日 | Y34: =(W34-V34-X34)*24 -> 0 | Z34: =Y34-T34 -> 0
B35: 46142 | C35: =TEXT(B35,"aaa") -> 木 | T35: =SUM(D35:S35) -> 0 | V35: 0.375 | W35: 0.72916667 | X35: 0.052083333 | Y35: =(W35-V35-X35)*24 -> 7.25 | Z35: =Y35-T35 -> 7.25 | AA35: =AC35-AB35 -> 0 | AB35: 7.25 | AC35: =ABS(Y35) -> 7.25
B37: 月 | C37: 合計 | D37: =SUM(D6:D36) -> 0 | E37: =SUM(E6:E36) -> 0 | F37: =SUM(F6:F36) -> 0 | G37: =SUM(G6:G36) -> 0 | H37: =SUM(H6:H36) -> 0 | I37: =SUM(I6:I36) -> 0 | J37: =SUM(J6:J36) -> 0 | K37: =SUM(K6:K36) -> 0 | ... T37: =SUM(T6:T36) -> 0 | AA37: =SUM(AA6:AA36) -> 0 | AB37: =SUM(AB6:AB36) -> 152.25
B40: 直接経費（交通費等） | T40: 合計（円） | U40: 備考
C41: =TEXT(B41,"aaa") -> 土 | T41: =SUM(D41:S41) -> 0
C42: =TEXT(B42,"aaa") -> 土 | T42: =SUM(D42:S42) -> 0
C43: =TEXT(B43,"aaa") -> 土 | T43: =SUM(D43:S43) -> 0
C44: =TEXT(B44,"aaa") -> 土 | T44: =SUM(D44:S44) -> 0
...

Sheet 5月
B2: No. （件番SheetのNo.を入力⇒） | S2: 99
B3: 件番（自動入力） | D3: =IF(ISERROR(VLOOKUP(D2,件番!$A$10:$D$113,2,FALSE)),"",(VLOOKUP(D2,件番!$A$10:$D$113,2,FALSE))) | E3: =IF(ISERROR(VLOOKUP(E2,件番!$A$10:$D$113,2,FALSE)),"",(VLOOKUP(E2,件番!$A$10:$D$113,2,FALSE))) | F3: =IF(ISERROR(VLOOKUP(F2,件番!$A$10:$D$113,2,FALSE)),"",(VLOOKUP(F2,件番!$A$10:$D$113,2,FALSE))) | G3: =IF(ISERROR(VLOOKUP(G2,件番!$A$10:$D$113,2,FALSE)),"",(VLOOKUP(G2,件番!$A$10:$D$113,2,FALSE))) | H3: =IF(ISERROR(VLOOKUP(H2,件番!$A$10:$D$113,2,FALSE)),"",(VLOOKUP(H2,件番!$A$10:$D$113,2,FALSE))) | I3: =IF(ISERROR(VLOOKUP(I2,件番!$A$10:$D$113,2,FALSE)),"",(VLOOKUP(I2,件番!$A$10:$D$113,2,FALSE))) | J3: =IF(ISERROR(VLOOKUP(J2,件番!$A$10:$D$113,2,FALSE)),"",(VLOOKUP(J2,件番!$A$10:$D$113,2,FALSE))) | K3: =IF(ISERROR(VLOOKUP(K2,件番!$A$10:$D$113,2,FALSE)),"",(VLOOKUP(K2,件番!$A$10:$D$113,2,FALSE))) | ... O3: =IF(ISERROR(VLOOKUP(O2,件番!$A$10:$D$113,2,FALSE)),"",(VLOOKUP(O2,件番!$A$10:$D$113,2,FALSE))) | S3: =IF(ISERROR(VLOOKUP(S2,件番!$A$3:$D$113,2,FALSE)),"",(VLOOKUP(S2,件番!$A$3:$D$113,2,FALSE))) -> 2032B1008
B4: 件名（自動入力） | D4: =IF(ISERROR(VLOOKUP(D2,件番!$A$10:$D$113,2,FALSE)),"",(VLOOKUP(D2,件番!$A$10:$D$113,3,FALSE))) | E4: =IF(ISERROR(VLOOKUP(E2,件番!$A$10:$D$113,2,FALSE)),"",(VLOOKUP(E2,件番!$A$10:$D$113,3,FALSE))) | F4: =IF(ISERROR(VLOOKUP(F2,件番!$A$10:$D$113,2,FALSE)),"",(VLOOKUP(F2,件番!$A$10:$D$113,3,FALSE))) | G4: =IF(ISERROR(VLOOKUP(G2,件番!$A$10:$D$113,2,FALSE)),"",(VLOOKUP(G2,件番!$A$10:$D$113,3,FALSE))) | H4: =IF(ISERROR(VLOOKUP(H2,件番!$A$10:$D$113,2,FALSE)),"",(VLOOKUP(H2,件番!$A$10:$D$113,3,FALSE))) | I4: =IF(ISERROR(VLOOKUP(I2,件番!$A$10:$D$113,2,FALSE)),"",(VLOOKUP(I2,件番!$A$10:$D$113,3,FALSE))) | J4: =IF(ISERROR(VLOOKUP(J2,件番!$A$10:$D$113,2,FALSE)),"",(VLOOKUP(J2,件番!$A$10:$D$113,3,FALSE))) | K4: =IF(ISERROR(VLOOKUP(K2,件番!$A$10:$D$113,2,FALSE)),"",(VLOOKUP(K2,件番!$A$10:$D$113,3,FALSE))) | ... O4: =IF(ISERROR(VLOOKUP(O2,件番!$A$10:$D$113,2,FALSE)),"",(VLOOKUP(O2,件番!$A$10:$D$113,3,FALSE))) | S4: =IF(ISERROR(VLOOKUP(S2,件番!$A$3:$D$113,2,FALSE)),"",(VLOOKUP(S2,件番!$A$3:$D$113,3,FALSE))) -> 関東交通整備
B5: 管理（自動入力） | D5: =IF(ISERROR(VLOOKUP(D2,件番!$A$10:$D$113,2,FALSE)),"",(VLOOKUP(D2,件番!$A$10:$D$113,4,FALSE))) | E5: =IF(ISERROR(VLOOKUP(E2,件番!$A$10:$D$113,2,FALSE)),"",(VLOOKUP(E2,件番!$A$10:$D$113,4,FALSE))) | F5: =IF(ISERROR(VLOOKUP(F2,件番!$A$10:$D$113,2,FALSE)),"",(VLOOKUP(F2,件番!$A$10:$D$113,4,FALSE))) | G5: =IF(ISERROR(VLOOKUP(G2,件番!$A$10:$D$113,2,FALSE)),"",(VLOOKUP(G2,件番!$A$10:$D$113,4,FALSE))) | H5: =IF(ISERROR(VLOOKUP(H2,件番!$A$10:$D$113,2,FALSE)),"",(VLOOKUP(H2,件番!$A$10:$D$113,4,FALSE))) | I5: =IF(ISERROR(VLOOKUP(I2,件番!$A$10:$D$113,2,FALSE)),"",(VLOOKUP(I2,件番!$A$10:$D$113,4,FALSE))) | J5: =IF(ISERROR(VLOOKUP(J2,件番!$A$10:$D$113,2,FALSE)),"",(VLOOKUP(J2,件番!$A$10:$D$113,4,FALSE))) | K5: =IF(ISERROR(VLOOKUP(K2,件番!$A$10:$D$113,2,FALSE)),"",(VLOOKUP(K2,件番!$A$10:$D$113,4,FALSE))) | ... O5: =IF(ISERROR(VLOOKUP(O2,件番!$A$10:$D$113,2,FALSE)),"",(VLOOKUP(O2,件番!$A$10:$D$113,4,FALSE))) | S5: =IF(ISERROR(VLOOKUP(S2,件番!$A$3:$D$113,2,FALSE)),"",(VLOOKUP(S2,件番!$A$3:$D$113,4,FALSE))) -> 0 | T5: 合計 | U5: 備考 | V5: 始業 | W5: 終業 | X5: 休憩 | Y5: 就業時間 | Z5: チェック
B6: 46143 | C6: =TEXT(B6,"aaa") -> 金 | T6: =SUM(D6:S6) -> 0 | V6: 0.375 | W6: 0.72916667 | X6: 0.052083333 | Y6: =(W6-V6-X6)*24 -> 7.25 | Z6: =Y6-T6 -> 7.25 | AA6: =AC6-AB6 -> 0 | AB6: 7.25 | AC6: =ABS(Y6) -> 7.25
B7: 46144 | C7: =TEXT(B7,"aaa") -> 土 | T7: =SUM(D7:S7) -> 0 | Y7: =(W7-V7-X7)*24 -> 0 | Z7: =Y7-T7 -> 0
B8: 46145 | C8: =TEXT(B8,"aaa") -> 日 | T8: =SUM(D8:S8) -> 0 | U8: 憲法記念日 | Y8: =(W8-V8-X8)*24 -> 0 | Z8: =Y8-T8 -> 0
B9: 46146 | C9: =TEXT(B9,"aaa") -> 月 | T9: =SUM(D9:S9) -> 0 | U9: みどりの日 | Y9: =(W9-V9-X9)*24 -> 0 | Z9: =Y9-T9 -> 0
B10: 46147 | C10: =TEXT(B10,"aaa") -> 火 | T10: =SUM(D10:S10) -> 0 | U10: こどもの日 | Y10: =(W10-V10-X10)*24 -> 0 | Z10: =Y10-T10 -> 0
B11: 46148 | C11: =TEXT(B11,"aaa") -> 水 | T11: =SUM(D11:S11) -> 0 | U11: 振替休日 | Y11: =(W11-V11-X11)*24 -> 0 | Z11: =Y11-T11 -> 0
B12: 46149 | C12: =TEXT(B12,"aaa") -> 木 | T12: =SUM(D12:S12) -> 0 | V12: 0.375 | W12: 0.72916667 | X12: 0.052083333 | Y12: =(W12-V12-X12)*24 -> 7.25 | Z12: =Y12-T12 -> 7.25 | AA12: =AC12-AB12 -> 0 | AB12: 7.25 | AC12: =ABS(Y12) -> 7.25
B13: 46150 | C13: =TEXT(B13,"aaa") -> 金 | T13: =SUM(D13:S13) -> 0 | V13: 0.375 | W13: 0.72916667 | X13: 0.052083333 | Y13: =(W13-V13-X13)*24 -> 7.25 | Z13: =Y13-T13 -> 7.25 | AA13: =AC13-AB13 -> 0 | AB13: 7.25 | AC13: =ABS(Y13) -> 7.25
B14: 46151 | C14: =TEXT(B14,"aaa") -> 土 | T14: =SUM(D14:S14) -> 0 | Y14: =(W14-V14-X14)*24 -> 0 | Z14: =Y14-T14 -> 0
B15: 46152 | C15: =TEXT(B15,"aaa") -> 日 | T15: =SUM(D15:S15) -> 0 | Y15: =(W15-V15-X15)*24 -> 0 | Z15: =Y15-T15 -> 0
B16: 46153 | C16: =TEXT(B16,"aaa") -> 月 | T16: =SUM(D16:S16) -> 0 | V16: 0.375 | W16: 0.72916667 | X16: 0.052083333 | Y16: =(W16-V16-X16)*24 -> 7.25 | Z16: =Y16-T16 -> 7.25 | AA16: =AC16-AB16 -> 0 | AB16: 7.25 | AC16: =ABS(Y16) -> 7.25
B17: 46154 | C17: =TEXT(B17,"aaa") -> 火 | T17: =SUM(D17:S17) -> 0 | V17: 0.375 | W17: 0.72916667 | X17: 0.052083333 | Y17: =(W17-V17-X17)*24 -> 7.25 | Z17: =Y17-T17 -> 7.25 | AA17: =AC17-AB17 -> 0 | AB17: 7.25 | AC17: =ABS(Y17) -> 7.25
B18: 46155 | C18: =TEXT(B18,"aaa") -> 水 | T18: =SUM(D18:S18) -> 0 | V18: 0.375 | W18: 0.72916667 | X18: 0.052083333 | Y18: =(W18-V18-X18)*24 -> 7.25 | Z18: =Y18-T18 -> 7.25 | AA18: =AC18-AB18 -> 0 | AB18: 7.25 | AC18: =ABS(Y18) -> 7.25
B19: 46156 | C19: =TEXT(B19,"aaa") -> 木 | T19: =SUM(D19:S19) -> 0 | V19: 0.375 | W19: 0.72916667 | X19: 0.052083333 | Y19: =(W19-V19-X19)*24 -> 7.25 | Z19: =Y19-T19 -> 7.25 | AA19: =AC19-AB19 -> 0 | AB19: 7.25 | AC19: =ABS(Y19) -> 7.25
B20: 46157 | C20: =TEXT(B20,"aaa") -> 金 | T20: =SUM(D20:S20) -> 0 | V20: 0.375 | W20: 0.72916667 | X20: 0.052083333 | Y20: =(W20-V20-X20)*24 -> 7.25 | Z20: =Y20-T20 -> 7.25 | AA20: =AC20-AB20 -> 0 | AB20: 7.25 | AC20: =ABS(Y20) -> 7.25
B21: 46158 | C21: =TEXT(B21,"aaa") -> 土 | T21: =SUM(D21:S21) -> 0 | Y21: =(W21-V21-X21)*24 -> 0 | Z21: =Y21-T21 -> 0
B22: 46159 | C22: =TEXT(B22,"aaa") -> 日 | T22: =SUM(D22:S22) -> 0 | Y22: =(W22-V22-X22)*24 -> 0 | Z22: =Y22-T22 -> 0
B23: 46160 | C23: =TEXT(B23,"aaa") -> 月 | T23: =SUM(D23:S23) -> 0 | V23: 0.375 | W23: 0.72916667 | X23: 0.052083333 | Y23: =(W23-V23-X23)*24 -> 7.25 | Z23: =Y23-T23 -> 7.25 | AA23: =AC23-AB23 -> 0 | AB23: 7.25 | AC23: =ABS(Y23) -> 7.25
B24: 46161 | C24: =TEXT(B24,"aaa") -> 火 | T24: =SUM(D24:S24) -> 0 | V24: 0.375 | W24: 0.72916667 | X24: 0.052083333 | Y24: =(W24-V24-X24)*24 -> 7.25 | Z24: =Y24-T24 -> 7.25 | AA24: =AC24-AB24 -> 0 | AB24: 7.25 | AC24: =ABS(Y24) -> 7.25
B25: 46162 | C25: =TEXT(B25,"aaa") -> 水 | T25: =SUM(D25:S25) -> 0 | V25: 0.375 | W25: 0.72916667 | X25: 0.052083333 | Y25: =(W25-V25-X25)*24 -> 7.25 | Z25: =Y25-T25 -> 7.25 | AA25: =AC25-AB25 -> 0 | AB25: 7.25 | AC25: =ABS(Y25) -> 7.25
B26: 46163 | C26: =TEXT(B26,"aaa") -> 木 | T26: =SUM(D26:S26) -> 0 | V26: 0.375 | W26: 0.72916667 | X26: 0.052083333 | Y26: =(W26-V26-X26)*24 -> 7.25 | Z26: =Y26-T26 -> 7.25 | AA26: =AC26-AB26 -> 0 | AB26: 7.25 | AC26: =ABS(Y26) -> 7.25
B27: 46164 | C27: =TEXT(B27,"aaa") -> 金 | T27: =SUM(D27:S27) -> 0 | V27: 0.375 | W27: 0.72916667 | X27: 0.052083333 | Y27: =(W27-V27-X27)*24 -> 7.25 | Z27: =Y27-T27 -> 7.25 | AA27: =AC27-AB27 -> 0 | AB27: 7.25 | AC27: =ABS(Y27) -> 7.25
B28: 46165 | C28: =TEXT(B28,"aaa") -> 土 | T28: =SUM(D28:S28) -> 0 | Y28: =(W28-V28-X28)*24 -> 0 | Z28: =Y28-T28 -> 0
B29: 46166 | C29: =TEXT(B29,"aaa") -> 日 | T29: =SUM(D29:S29) -> 0 | Y29: =(W29-V29-X29)*24 -> 0 | Z29: =Y29-T29 -> 0
B30: 46167 | C30: =TEXT(B30,"aaa") -> 月 | T30: =SUM(D30:S30) -> 0 | V30: 0.375 | W30: 0.72916667 | X30: 0.052083333 | Y30: =(W30-V30-X30)*24 -> 7.25 | Z30: =Y30-T30 -> 7.25 | AA30: =AC30-AB30 -> 0 | AB30: 7.25 | AC30: =ABS(Y30) -> 7.25
B31: 46168 | C31: =TEXT(B31,"aaa") -> 火 | T31: =SUM(D31:S31) -> 0 | V31: 0.375 | W31: 0.72916667 | X31: 0.052083333 | Y31: =(W31-V31-X31)*24 -> 7.25 | Z31: =Y31-T31 -> 7.25 | AA31: =AC31-AB31 -> 0 | AB31: 7.25 | AC31: =ABS(Y31) -> 7.25
B32: 46169 | C32: =TEXT(B32,"aaa") -> 水 | T32: =SUM(D32:S32) -> 0 | V32: 0.375 | W32: 0.72916667 | X32: 0.052083333 | Y32: =(W32-V32-X32)*24 -> 7.25 | Z32: =Y32-T32 -> 7.25 | AA32: =AC32-AB32 -> 0 | AB32: 7.25 | AC32: =ABS(Y32) -> 7.25
B33: 46170 | C33: =TEXT(B33,"aaa") -> 木 | T33: =SUM(D33:S33) -> 0 | V33: 0.375 | W33: 0.72916667 | X33: 0.052083333 | Y33: =(W33-V33-X33)*24 -> 7.25 | Z33: =Y33-T33 -> 7.25 | AA33: =AC33-AB33 -> 0 | AB33: 7.25 | AC33: =ABS(Y33) -> 7.25
B34: 46171 | C34: =TEXT(B34,"aaa") -> 金 | T34: =SUM(D34:S34) -> 0 | V34: 0.375 | W34: 0.72916667 | X34: 0.052083333 | Y34: =(W34-V34-X34)*24 -> 7.25 | Z34: =Y34-T34 -> 7.25 | AA34: =AC34-AB34 -> 0 | AB34: 7.25 | AC34: =ABS(Y34) -> 7.25
B35: 46172 | C35: =TEXT(B35,"aaa") -> 土 | T35: =SUM(D35:S35) -> 0 | Y35: =(W35-V35-X35)*24 -> 0 | Z35: =Y35-T35 -> 0
B36: 46173 | C36: =TEXT(B36,"aaa") -> 日 | T36: =SUM(D36:S36) -> 0 | Y36: =(W36-V36-X36)*24 -> 0 | Z36: =Y36-T36 -> 0
B37: 月 | C37: 合計 | D37: =SUM(D6:D36) -> 0 | E37: =SUM(E6:E36) -> 0 | F37: =SUM(F6:F36) -> 0 | G37: =SUM(G6:G36) -> 0 | H37: =SUM(H6:H36) -> 0 | I37: =SUM(I6:I36) -> 0 | J37: =SUM(J6:J36) -> 0 | K37: =SUM(K6:K36) -> 0 | ... T37: =SUM(T6:T36) -> 0 | AA37: =SUM(AA6:AA36) -> 0 | AB37: =SUM(AB6:AB36) -> 130.5
B40: 直接経費（交通費等） | T40: 合計（円） | U40: 備考
C41: =TEXT(B41,"aaa") -> 土 | T41: =SUM(D41:S41) -> 0
C42: =TEXT(B42,"aaa") -> 土 | T42: =SUM(D42:S42) -> 0
C43: =TEXT(B43,"aaa") -> 土 | T43: =SUM(D43:S43) -> 0
...

Sheet 6月
B2: No. （件番SheetのNo.を入力⇒） | S2: 99
B3: 件番（自動入力） | D3: =IF(ISERROR(VLOOKUP(D2,件番!$A$10:$D$113,2,FALSE)),"",(VLOOKUP(D2,件番!$A$10:$D$113,2,FALSE))) | E3: =IF(ISERROR(VLOOKUP(E2,件番!$A$10:$D$113,2,FALSE)),"",(VLOOKUP(E2,件番!$A$10:$D$113,2,FALSE))) | F3: =IF(ISERROR(VLOOKUP(F2,件番!$A$10:$D$113,2,FALSE)),"",(VLOOKUP(F2,件番!$A$10:$D$113,2,FALSE))) | G3: =IF(ISERROR(VLOOKUP(G2,件番!$A$10:$D$113,2,FALSE)),"",(VLOOKUP(G2,件番!$A$10:$D$113,2,FALSE))) | H3: =IF(ISERROR(VLOOKUP(H2,件番!$A$10:$D$113,2,FALSE)),"",(VLOOKUP(H2,件番!$A$10:$D$113,2,FALSE))) | I3: =IF(ISERROR(VLOOKUP(I2,件番!$A$10:$D$113,2,FALSE)),"",(VLOOKUP(I2,件番!$A$10:$D$113,2,FALSE))) | J3: =IF(ISERROR(VLOOKUP(J2,件番!$A$10:$D$113,2,FALSE)),"",(VLOOKUP(J2,件番!$A$10:$D$113,2,FALSE))) | K3: =IF(ISERROR(VLOOKUP(K2,件番!$A$10:$D$113,2,FALSE)),"",(VLOOKUP(K2,件番!$A$10:$D$113,2,FALSE))) | ... O3: =IF(ISERROR(VLOOKUP(O2,件番!$A$10:$D$113,2,FALSE)),"",(VLOOKUP(O2,件番!$A$10:$D$113,2,FALSE))) | R3: =IF(ISERROR(VLOOKUP(R2,件番!$A$10:$D$113,2,FALSE)),"",(VLOOKUP(R2,件番!$A$10:$D$113,2,FALSE))) | S3: =IF(ISERROR(VLOOKUP(S2,件番!$A$3:$D$113,2,FALSE)),"",(VLOOKUP(S2,件番!$A$3:$D$113,2,FALSE))) -> 2032B1008
B4: 件名（自動入力） | D4: =IF(ISERROR(VLOOKUP(D2,件番!$A$10:$D$113,2,FALSE)),"",(VLOOKUP(D2,件番!$A$10:$D$113,3,FALSE))) | E4: =IF(ISERROR(VLOOKUP(E2,件番!$A$10:$D$113,2,FALSE)),"",(VLOOKUP(E2,件番!$A$10:$D$113,3,FALSE))) | F4: =IF(ISERROR(VLOOKUP(F2,件番!$A$10:$D$113,2,FALSE)),"",(VLOOKUP(F2,件番!$A$10:$D$113,3,FALSE))) | G4: =IF(ISERROR(VLOOKUP(G2,件番!$A$10:$D$113,2,FALSE)),"",(VLOOKUP(G2,件番!$A$10:$D$113,3,FALSE))) | H4: =IF(ISERROR(VLOOKUP(H2,件番!$A$10:$D$113,2,FALSE)),"",(VLOOKUP(H2,件番!$A$10:$D$113,3,FALSE))) | I4: =IF(ISERROR(VLOOKUP(I2,件番!$A$10:$D$113,2,FALSE)),"",(VLOOKUP(I2,件番!$A$10:$D$113,3,FALSE))) | J4: =IF(ISERROR(VLOOKUP(J2,件番!$A$10:$D$113,2,FALSE)),"",(VLOOKUP(J2,件番!$A$10:$D$113,3,FALSE))) | K4: =IF(ISERROR(VLOOKUP(K2,件番!$A$10:$D$113,2,FALSE)),"",(VLOOKUP(K2,件番!$A$10:$D$113,3,FALSE))) | ... O4: =IF(ISERROR(VLOOKUP(O2,件番!$A$10:$D$113,2,FALSE)),"",(VLOOKUP(O2,件番!$A$10:$D$113,3,FALSE))) | R4: =IF(ISERROR(VLOOKUP(R2,件番!$A$10:$D$113,2,FALSE)),"",(VLOOKUP(R2,件番!$A$10:$D$113,3,FALSE))) | S4: =IF(ISERROR(VLOOKUP(S2,件番!$A$3:$D$113,2,FALSE)),"",(VLOOKUP(S2,件番!$A$3:$D$113,3,FALSE))) -> 関東交通整備
B5: 管理（自動入力） | D5: =IF(ISERROR(VLOOKUP(D2,件番!$A$10:$D$113,2,FALSE)),"",(VLOOKUP(D2,件番!$A$10:$D$113,4,FALSE))) | E5: =IF(ISERROR(VLOOKUP(E2,件番!$A$10:$D$113,2,FALSE)),"",(VLOOKUP(E2,件番!$A$10:$D$113,4,FALSE))) | F5: =IF(ISERROR(VLOOKUP(F2,件番!$A$10:$D$113,2,FALSE)),"",(VLOOKUP(F2,件番!$A$10:$D$113,4,FALSE))) | G5: =IF(ISERROR(VLOOKUP(G2,件番!$A$10:$D$113,2,FALSE)),"",(VLOOKUP(G2,件番!$A$10:$D$113,4,FALSE))) | H5: =IF(ISERROR(VLOOKUP(H2,件番!$A$10:$D$113,2,FALSE)),"",(VLOOKUP(H2,件番!$A$10:$D$113,4,FALSE))) | I5: =IF(ISERROR(VLOOKUP(I2,件番!$A$10:$D$113,2,FALSE)),"",(VLOOKUP(I2,件番!$A$10:$D$113,4,FALSE))) | J5: =IF(ISERROR(VLOOKUP(J2,件番!$A$10:$D$113,2,FALSE)),"",(VLOOKUP(J2,件番!$A$10:$D$113,4,FALSE))) | K5: =IF(ISERROR(VLOOKUP(K2,件番!$A$10:$D$113,2,FALSE)),"",(VLOOKUP(K2,件番!$A$10:$D$113,4,FALSE))) | ... O5: =IF(ISERROR(VLOOKUP(O2,件番!$A$10:$D$113,2,FALSE)),"",(VLOOKUP(O2,件番!$A$10:$D$113,4,FALSE))) | T5: 合計 | U5: 備考 | V5: 始業 | W5: 終業 | X5: 休憩 | Y5: 就業時間 | Z5: チェック
B6: 46174 | C6: =TEXT(B6,"aaa") -> 月 | T6: =SUM(D6:S6) -> 0 | V6: 0.375 | W6: 0.72916667 | X6: 0.052083333 | Y6: =(W6-V6-X6)*24 -> 7.25 | Z6: =Y6-T6 -> 7.25 | AA6: =AC6-AB6 -> 0 | AB6: 7.25 | AC6: =ABS(Y6) -> 7.25
B7: 46175 | C7: =TEXT(B7,"aaa") -> 火 | T7: =SUM(D7:S7) -> 0 | V7: 0.375 | W7: 0.72916667 | X7: 0.052083333 | Y7: =(W7-V7-X7)*24 -> 7.25 | Z7: =Y7-T7 -> 7.25 | AA7: =AC7-AB7 -> 0 | AB7: 7.25 | AC7: =ABS(Y7) -> 7.25
B8: 46176 | C8: =TEXT(B8,"aaa") -> 水 | T8: =SUM(D8:S8) -> 0 | V8: 0.375 | W8: 0.72916667 | X8: 0.052083333 | Y8: =(W8-V8-X8)*24 -> 7.25 | Z8: =Y8-T8 -> 7.25 | AA8: =AC8-AB8 -> 0 | AB8: 7.25 | AC8: =ABS(Y8) -> 7.25
B9: 46177 | C9: =TEXT(B9,"aaa") -> 木 | T9: =SUM(D9:S9) -> 0 | V9: 0.375 | W9: 0.72916667 | X9: 0.052083333 | Y9: =(W9-V9-X9)*24 -> 7.25 | Z9: =Y9-T9 -> 7.25 | AA9: =AC9-AB9 -> 0 | AB9: 7.25 | AC9: =ABS(Y9) -> 7.25
B10: 46178 | C10: =TEXT(B10,"aaa") -> 金 | T10: =SUM(D10:S10) -> 0 | V10: 0.375 | W10: 0.72916667 | X10: 0.052083333 | Y10: =(W10-V10-X10)*24 -> 7.25 | Z10: =Y10-T10 -> 7.25 | AA10: =AC10-AB10 -> 0 | AB10: 7.25 | AC10: =ABS(Y10) -> 7.25
B11: 46179 | C11: =TEXT(B11,"aaa") -> 土 | T11: =SUM(D11:S11) -> 0 | Y11: =(W11-V11-X11)*24 -> 0 | Z11: =Y11-T11 -> 0
B12: 46180 | C12: =TEXT(B12,"aaa") -> 日 | T12: =SUM(D12:S12) -> 0 | Y12: =(W12-V12-X12)*24 -> 0 | Z12: =Y12-T12 -> 0
B13: 46181 | C13: =TEXT(B13,"aaa") -> 月 | T13: =SUM(D13:S13) -> 0 | V13: 0.375 | W13: 0.72916667 | X13: 0.052083333 | Y13: =(W13-V13-X13)*24 -> 7.25 | Z13: =Y13-T13 -> 7.25 | AA13: =AC13-AB13 -> 0 | AB13: 7.25 | AC13: =ABS(Y13) -> 7.25
B14: 46182 | C14: =TEXT(B14,"aaa") -> 火 | T14: =SUM(D14:S14) -> 0 | V14: 0.375 | W14: 0.72916667 | X14: 0.052083333 | Y14: =(W14-V14-X14)*24 -> 7.25 | Z14: =Y14-T14 -> 7.25 | AA14: =AC14-AB14 -> 0 | AB14: 7.25 | AC14: =ABS(Y14) -> 7.25
B15: 46183 | C15: =TEXT(B15,"aaa") -> 水 | T15: =SUM(D15:S15) -> 0 | V15: 0.375 | W15: 0.72916667 | X15: 0.052083333 | Y15: =(W15-V15-X15)*24 -> 7.25 | Z15: =Y15-T15 -> 7.25 | AA15: =AC15-AB15 -> 0 | AB15: 7.25 | AC15: =ABS(Y15) -> 7.25
B16: 46184 | C16: =TEXT(B16,"aaa") -> 木 | T16: =SUM(D16:S16) -> 0 | V16: 0.375 | W16: 0.72916667 | X16: 0.052083333 | Y16: =(W16-V16-X16)*24 -> 7.25 | Z16: =Y16-T16 -> 7.25 | AA16: =AC16-AB16 -> 0 | AB16: 7.25 | AC16: =ABS(Y16) -> 7.25
B17: 46185 | C17: =TEXT(B17,"aaa") -> 金 | T17: =SUM(D17:S17) -> 0 | V17: 0.375 | W17: 0.72916667 | X17: 0.052083333 | Y17: =(W17-V17-X17)*24 -> 7.25 | Z17: =Y17-T17 -> 7.25 | AA17: =AC17-AB17 -> 0 | AB17: 7.25 | AC17: =ABS(Y17) -> 7.25
B18: 46186 | C18: =TEXT(B18,"aaa") -> 土 | T18: =SUM(D18:S18) -> 0 | Y18: =(W18-V18-X18)*24 -> 0 | Z18: =Y18-T18 -> 0
B19: 46187 | C19: =TEXT(B19,"aaa") -> 日 | T19: =SUM(D19:S19) -> 0 | Y19: =(W19-V19-X19)*24 -> 0 | Z19: =Y19-T19 -> 0
B20: 46188 | C20: =TEXT(B20,"aaa") -> 月 | T20: =SUM(D20:S20) -> 0 | V20: 0.375 | W20: 0.72916667 | X20: 0.052083333 | Y20: =(W20-V20-X20)*24 -> 7.25 | Z20: =Y20-T20 -> 7.25 | AA20: =AC20-AB20 -> 0 | AB20: 7.25 | AC20: =ABS(Y20) -> 7.25
B21: 46189 | C21: =TEXT(B21,"aaa") -> 火 | T21: =SUM(D21:S21) -> 0 | V21: 0.375 | W21: 0.72916667 | X21: 0.052083333 | Y21: =(W21-V21-X21)*24 -> 7.25 | Z21: =Y21-T21 -> 7.25 | AA21: =AC21-AB21 -> 0 | AB21: 7.25 | AC21: =ABS(Y21) -> 7.25
B22: 46190 | C22: =TEXT(B22,"aaa") -> 水 | T22: =SUM(D22:S22) -> 0 | V22: 0.375 | W22: 0.72916667 | X22: 0.052083333 | Y22: =(W22-V22-X22)*24 -> 7.25 | Z22: =Y22-T22 -> 7.25 | AA22: =AC22-AB22 -> 0 | AB22: 7.25 | AC22: =ABS(Y22) -> 7.25
B23: 46191 | C23: =TEXT(B23,"aaa") -> 木 | T23: =SUM(D23:S23) -> 0 | V23: 0.375 | W23: 0.72916667 | X23: 0.052083333 | Y23: =(W23-V23-X23)*24 -> 7.25 | Z23: =Y23-T23 -> 7.25 | AA23: =AC23-AB23 -> 0 | AB23: 7.25 | AC23: =ABS(Y23) -> 7.25
B24: 46192 | C24: =TEXT(B24,"aaa") -> 金 | T24: =SUM(D24:S24) -> 0 | V24: 0.375 | W24: 0.72916667 | X24: 0.052083333 | Y24: =(W24-V24-X24)*24 -> 7.25 | Z24: =Y24-T24 -> 7.25 | AA24: =AC24-AB24 -> 0 | AB24: 7.25 | AC24: =ABS(Y24) -> 7.25
B25: 46193 | C25: =TEXT(B25,"aaa") -> 土 | T25: =SUM(D25:S25) -> 0 | Y25: =(W25-V25-X25)*24 -> 0 | Z25: =Y25-T25 -> 0
B26: 46194 | C26: =TEXT(B26,"aaa") -> 日 | T26: =SUM(D26:S26) -> 0 | Y26: =(W26-V26-X26)*24 -> 0 | Z26: =Y26-T26 -> 0
B27: 46195 | C27: =TEXT(B27,"aaa") -> 月 | T27: =SUM(D27:S27) -> 0 | V27: 0.375 | W27: 0.72916667 | X27: 0.052083333 | Y27: =(W27-V27-X27)*24 -> 7.25 | Z27: =Y27-T27 -> 7.25 | AA27: =AC27-AB27 -> 0 | AB27: 7.25 | AC27: =ABS(Y27) -> 7.25
B28: 46196 | C28: =TEXT(B28,"aaa") -> 火 | T28: =SUM(D28:S28) -> 0 | V28: 0.375 | W28: 0.72916667 | X28: 0.052083333 | Y28: =(W28-V28-X28)*24 -> 7.25 | Z28: =Y28-T28 -> 7.25 | AA28: =AC28-AB28 -> 0 | AB28: 7.25 | AC28: =ABS(Y28) -> 7.25
B29: 46197 | C29: =TEXT(B29,"aaa") -> 水 | T29: =SUM(D29:S29) -> 0 | V29: 0.375 | W29: 0.72916667 | X29: 0.052083333 | Y29: =(W29-V29-X29)*24 -> 7.25 | Z29: =Y29-T29 -> 7.25 | AA29: =AC29-AB29 -> 0 | AB29: 7.25 | AC29: =ABS(Y29) -> 7.25
B30: 46198 | C30: =TEXT(B30,"aaa") -> 木 | T30: =SUM(D30:S30) -> 0 | V30: 0.375 | W30: 0.72916667 | X30: 0.052083333 | Y30: =(W30-V30-X30)*24 -> 7.25 | Z30: =Y30-T30 -> 7.25 | AA30: =AC30-AB30 -> 0 | AB30: 7.25 | AC30: =ABS(Y30) -> 7.25
B31: 46199 | C31: =TEXT(B31,"aaa") -> 金 | T31: =SUM(D31:S31) -> 0 | V31: 0.375 | W31: 0.72916667 | X31: 0.052083333 | Y31: =(W31-V31-X31)*24 -> 7.25 | Z31: =Y31-T31 -> 7.25 | AA31: =AC31-AB31 -> 0 | AB31: 7.25 | AC31: =ABS(Y31) -> 7.25
B32: 46200 | C32: =TEXT(B32,"aaa") -> 土 | T32: =SUM(D32:S32) -> 0 | Y32: =(W32-V32-X32)*24 -> 0 | Z32: =Y32-T32 -> 0
B33: 46201 | C33: =TEXT(B33,"aaa") -> 日 | T33: =SUM(D33:S33) -> 0 | Y33: =(W33-V33-X33)*24 -> 0 | Z33: =Y33-T33 -> 0
B34: 46202 | C34: =TEXT(B34,"aaa") -> 月 | T34: =SUM(D34:S34) -> 0 | V34: 0.375 | W34: 0.72916667 | X34: 0.052083333 | Y34: =(W34-V34-X34)*24 -> 7.25 | Z34: =Y34-T34 -> 7.25 | AA34: =AC34-AB34 -> 0 | AB34: 7.25 | AC34: =ABS(Y34) -> 7.25
B35: 46203 | C35: =TEXT(B35,"aaa") -> 火 | T35: =SUM(D35:S35) -> 0 | V35: 0.375 | W35: 0.72916667 | X35: 0.052083333 | Y35: =(W35-V35-X35)*24 -> 7.25 | Z35: =Y35-T35 -> 7.25 | AA35: =AC35-AB35 -> 0 | AB35: 7.25 | AC35: =ABS(Y35) -> 7.25
B37: 月 | C37: 合計 | D37: =SUM(D6:D36) -> 0 | E37: =SUM(E6:E36) -> 0 | F37: =SUM(F6:F36) -> 0 | G37: =SUM(G6:G36) -> 0 | H37: =SUM(H6:H36) -> 0 | I37: =SUM(I6:I36) -> 0 | J37: =SUM(J6:J36) -> 0 | K37: =SUM(K6:K36) -> 0 | ... T37: =SUM(T6:T36) -> 0 | AA37: =SUM(AA6:AA36) -> 0 | AB37: =SUM(AB6:AB36) -> 159.5
B40: 直接経費（交通費等） | T40: 合計（円） | U40: 備考
C41: =TEXT(B41,"aaa") -> 土 | T41: =SUM(D41:S41) -> 0
C42: =TEXT(B42,"aaa") -> 土 | T42: =SUM(D42:S42) -> 0
C43: =TEXT(B43,"aaa") -> 土 | T43: =SUM(D43:S43) -> 0
C44: =TEXT(B44,"aaa") -> 土 | T44: =SUM(D44:S44) -> 0
...

Sheet 7月
B2: No. （件番SheetのNo.を入力⇒） | S2: 99
B3: 件番（自動入力） | D3: =IF(ISERROR(VLOOKUP(D2,件番!$A$10:$D$113,2,FALSE)),"",(VLOOKUP(D2,件番!$A$10:$D$113,2,FALSE))) | E3: =IF(ISERROR(VLOOKUP(E2,件番!$A$10:$D$113,2,FALSE)),"",(VLOOKUP(E2,件番!$A$10:$D$113,2,FALSE))) | F3: =IF(ISERROR(VLOOKUP(F2,件番!$A$10:$D$113,2,FALSE)),"",(VLOOKUP(F2,件番!$A$10:$D$113,2,FALSE))) | G3: =IF(ISERROR(VLOOKUP(G2,件番!$A$10:$D$113,2,FALSE)),"",(VLOOKUP(G2,件番!$A$10:$D$113,2,FALSE))) | H3: =IF(ISERROR(VLOOKUP(H2,件番!$A$10:$D$113,2,FALSE)),"",(VLOOKUP(H2,件番!$A$10:$D$113,2,FALSE))) | I3: =IF(ISERROR(VLOOKUP(I2,件番!$A$10:$D$113,2,FALSE)),"",(VLOOKUP(I2,件番!$A$10:$D$113,2,FALSE))) | J3: =IF(ISERROR(VLOOKUP(J2,件番!$A$10:$D$113,2,FALSE)),"",(VLOOKUP(J2,件番!$A$10:$D$113,2,FALSE))) | K3: =IF(ISERROR(VLOOKUP(K2,件番!$A$10:$D$113,2,FALSE)),"",(VLOOKUP(K2,件番!$A$10:$D$113,2,FALSE))) | ... O3: =IF(ISERROR(VLOOKUP(O2,件番!$A$10:$D$113,2,FALSE)),"",(VLOOKUP(O2,件番!$A$10:$D$113,2,FALSE))) | S3: =IF(ISERROR(VLOOKUP(S2,件番!$A$3:$D$113,2,FALSE)),"",(VLOOKUP(S2,件番!$A$3:$D$113,2,FALSE))) -> 2032B1008
B4: 件名（自動入力） | D4: =IF(ISERROR(VLOOKUP(D2,件番!$A$10:$D$113,2,FALSE)),"",(VLOOKUP(D2,件番!$A$10:$D$113,3,FALSE))) | E4: =IF(ISERROR(VLOOKUP(E2,件番!$A$10:$D$113,2,FALSE)),"",(VLOOKUP(E2,件番!$A$10:$D$113,3,FALSE))) | F4: =IF(ISERROR(VLOOKUP(F2,件番!$A$10:$D$113,2,FALSE)),"",(VLOOKUP(F2,件番!$A$10:$D$113,3,FALSE))) | G4: =IF(ISERROR(VLOOKUP(G2,件番!$A$10:$D$113,2,FALSE)),"",(VLOOKUP(G2,件番!$A$10:$D$113,3,FALSE))) | H4: =IF(ISERROR(VLOOKUP(H2,件番!$A$10:$D$113,2,FALSE)),"",(VLOOKUP(H2,件番!$A$10:$D$113,3,FALSE))) | I4: =IF(ISERROR(VLOOKUP(I2,件番!$A$10:$D$113,2,FALSE)),"",(VLOOKUP(I2,件番!$A$10:$D$113,3,FALSE))) | J4: =IF(ISERROR(VLOOKUP(J2,件番!$A$10:$D$113,2,FALSE)),"",(VLOOKUP(J2,件番!$A$10:$D$113,3,FALSE))) | K4: =IF(ISERROR(VLOOKUP(K2,件番!$A$10:$D$113,2,FALSE)),"",(VLOOKUP(K2,件番!$A$10:$D$113,3,FALSE))) | ... O4: =IF(ISERROR(VLOOKUP(O2,件番!$A$10:$D$113,2,FALSE)),"",(VLOOKUP(O2,件番!$A$10:$D$113,3,FALSE))) | S4: =IF(ISERROR(VLOOKUP(S2,件番!$A$3:$D$113,2,FALSE)),"",(VLOOKUP(S2,件番!$A$3:$D$113,3,FALSE))) -> 関東交通整備
B5: 管理（自動入力） | D5: =IF(ISERROR(VLOOKUP(D2,件番!$A$10:$D$113,2,FALSE)),"",(VLOOKUP(D2,件番!$A$10:$D$113,4,FALSE))) | E5: =IF(ISERROR(VLOOKUP(E2,件番!$A$10:$D$113,2,FALSE)),"",(VLOOKUP(E2,件番!$A$10:$D$113,4,FALSE))) | F5: =IF(ISERROR(VLOOKUP(F2,件番!$A$10:$D$113,2,FALSE)),"",(VLOOKUP(F2,件番!$A$10:$D$113,4,FALSE))) | G5: =IF(ISERROR(VLOOKUP(G2,件番!$A$10:$D$113,2,FALSE)),"",(VLOOKUP(G2,件番!$A$10:$D$113,4,FALSE))) | H5: =IF(ISERROR(VLOOKUP(H2,件番!$A$10:$D$113,2,FALSE)),"",(VLOOKUP(H2,件番!$A$10:$D$113,4,FALSE))) | I5: =IF(ISERROR(VLOOKUP(I2,件番!$A$10:$D$113,2,FALSE)),"",(VLOOKUP(I2,件番!$A$10:$D$113,4,FALSE))) | J5: =IF(ISERROR(VLOOKUP(J2,件番!$A$10:$D$113,2,FALSE)),"",(VLOOKUP(J2,件番!$A$10:$D$113,4,FALSE))) | K5: =IF(ISERROR(VLOOKUP(K2,件番!$A$10:$D$113,2,FALSE)),"",(VLOOKUP(K2,件番!$A$10:$D$113,4,FALSE))) | ... O5: =IF(ISERROR(VLOOKUP(O2,件番!$A$10:$D$113,2,FALSE)),"",(VLOOKUP(O2,件番!$A$10:$D$113,4,FALSE))) | T5: 合計 | U5: 備考 | V5: 始業 | W5: 終業 | X5: 休憩 | Y5: 就業時間 | Z5: チェック
B6: 46204 | C6: =TEXT(B6,"aaa") -> 水 | T6: =SUM(D6:S6) -> 0 | V6: 0.375 | W6: 0.72916667 | X6: 0.052083333 | Y6: =(W6-V6-X6)*24 -> 7.25 | Z6: =Y6-T6 -> 7.25 | AA6: =AC6-AB6 -> 0 | AB6: 7.25 | AC6: =ABS(Y6) -> 7.25
B7: 46205 | C7: =TEXT(B7,"aaa") -> 木 | T7: =SUM(D7:S7) -> 0 | V7: 0.375 | W7: 0.72916667 | X7: 0.052083333 | Y7: =(W7-V7-X7)*24 -> 7.25 | Z7: =Y7-T7 -> 7.25 | AA7: =AC7-AB7 -> 0 | AB7: 7.25 | AC7: =ABS(Y7) -> 7.25
B8: 46206 | C8: =TEXT(B8,"aaa") -> 金 | T8: =SUM(D8:S8) -> 0 | V8: 0.375 | W8: 0.72916667 | X8: 0.052083333 | Y8: =(W8-V8-X8)*24 -> 7.25 | Z8: =Y8-T8 -> 7.25 | AA8: =AC8-AB8 -> 0 | AB8: 7.25 | AC8: =ABS(Y8) -> 7.25
B9: 46207 | C9: =TEXT(B9,"aaa") -> 土 | T9: =SUM(D9:S9) -> 0 | Y9: =(W9-V9-X9)*24 -> 0 | Z9: =Y9-T9 -> 0
B10: 46208 | C10: =TEXT(B10,"aaa") -> 日 | T10: =SUM(D10:S10) -> 0 | Y10: =(W10-V10-X10)*24 -> 0 | Z10: =Y10-T10 -> 0
B11: 46209 | C11: =TEXT(B11,"aaa") -> 月 | T11: =SUM(D11:S11) -> 0 | V11: 0.375 | W11: 0.72916667 | X11: 0.052083333 | Y11: =(W11-V11-X11)*24 -> 7.25 | Z11: =Y11-T11 -> 7.25 | AA11: =AC11-AB11 -> 0 | AB11: 7.25 | AC11: =ABS(Y11) -> 7.25
B12: 46210 | C12: =TEXT(B12,"aaa") -> 火 | T12: =SUM(D12:S12) -> 0 | V12: 0.375 | W12: 0.72916667 | X12: 0.052083333 | Y12: =(W12-V12-X12)*24 -> 7.25 | Z12: =Y12-T12 -> 7.25 | AA12: =AC12-AB12 -> 0 | AB12: 7.25 | AC12: =ABS(Y12) -> 7.25
B13: 46211 | C13: =TEXT(B13,"aaa") -> 水 | T13: =SUM(D13:S13) -> 0 | V13: 0.375 | W13: 0.72916667 | X13: 0.052083333 | Y13: =(W13-V13-X13)*24 -> 7.25 | Z13: =Y13-T13 -> 7.25 | AA13: =AC13-AB13 -> 0 | AB13: 7.25 | AC13: =ABS(Y13) -> 7.25
B14: 46212 | C14: =TEXT(B14,"aaa") -> 木 | T14: =SUM(D14:S14) -> 0 | V14: 0.375 | W14: 0.72916667 | X14: 0.052083333 | Y14: =(W14-V14-X14)*24 -> 7.25 | Z14: =Y14-T14 -> 7.25 | AA14: =AC14-AB14 -> 0 | AB14: 7.25 | AC14: =ABS(Y14) -> 7.25
B15: 46213 | C15: =TEXT(B15,"aaa") -> 金 | T15: =SUM(D15:S15) -> 0 | V15: 0.375 | W15: 0.72916667 | X15: 0.052083333 | Y15: =(W15-V15-X15)*24 -> 7.25 | Z15: =Y15-T15 -> 7.25 | AA15: =AC15-AB15 -> 0 | AB15: 7.25 | AC15: =ABS(Y15) -> 7.25
B16: 46214 | C16: =TEXT(B16,"aaa") -> 土 | T16: =SUM(D16:S16) -> 0 | Y16: =(W16-V16-X16)*24 -> 0 | Z16: =Y16-T16 -> 0
B17: 46215 | C17: =TEXT(B17,"aaa") -> 日 | T17: =SUM(D17:S17) -> 0 | Y17: =(W17-V17-X17)*24 -> 0 | Z17: =Y17-T17 -> 0
B18: 46216 | C18: =TEXT(B18,"aaa") -> 月 | T18: =SUM(D18:S18) -> 0 | V18: 0.375 | W18: 0.72916667 | X18: 0.052083333 | Y18: =(W18-V18-X18)*24 -> 7.25 | Z18: =Y18-T18 -> 7.25 | AA18: =AC18-AB18 -> 0 | AB18: 7.25 | AC18: =ABS(Y18) -> 7.25
B19: 46217 | C19: =TEXT(B19,"aaa") -> 火 | T19: =SUM(D19:S19) -> 0 | V19: 0.375 | W19: 0.72916667 | X19: 0.052083333 | Y19: =(W19-V19-X19)*24 -> 7.25 | Z19: =Y19-T19 -> 7.25 | AA19: =AC19-AB19 -> 0 | AB19: 7.25 | AC19: =ABS(Y19) -> 7.25
B20: 46218 | C20: =TEXT(B20,"aaa") -> 水 | T20: =SUM(D20:S20) -> 0 | V20: 0.375 | W20: 0.72916667 | X20: 0.052083333 | Y20: =(W20-V20-X20)*24 -> 7.25 | Z20: =Y20-T20 -> 7.25 | AA20: =AC20-AB20 -> 0 | AB20: 7.25 | AC20: =ABS(Y20) -> 7.25
B21: 46219 | C21: =TEXT(B21,"aaa") -> 木 | T21: =SUM(D21:S21) -> 0 | V21: 0.375 | W21: 0.72916667 | X21: 0.052083333 | Y21: =(W21-V21-X21)*24 -> 7.25 | Z21: =Y21-T21 -> 7.25 | AA21: =AC21-AB21 -> 0 | AB21: 7.25 | AC21: =ABS(Y21) -> 7.25
B22: 46220 | C22: =TEXT(B22,"aaa") -> 金 | T22: =SUM(D22:S22) -> 0 | V22: 0.375 | W22: 0.72916667 | X22: 0.052083333 | Y22: =(W22-V22-X22)*24 -> 7.25 | Z22: =Y22-T22 -> 7.25 | AA22: =AC22-AB22 -> 0 | AB22: 7.25 | AC22: =ABS(Y22) -> 7.25
B23: 46221 | C23: =TEXT(B23,"aaa") -> 土 | T23: =SUM(D23:S23) -> 0 | Y23: =(W23-V23-X23)*24 -> 0 | Z23: =Y23-T23 -> 0
B24: 46222 | C24: =TEXT(B24,"aaa") -> 日 | T24: =SUM(D24:S24) -> 0 | Y24: =(W24-V24-X24)*24 -> 0 | Z24: =Y24-T24 -> 0
B25: 46223 | C25: =TEXT(B25,"aaa") -> 月 | T25: =SUM(D25:S25) -> 0 | U25: 海の日 | Y25: =(W25-V25-X25)*24 -> 0 | Z25: =Y25-T25 -> 0
B26: 46224 | C26: =TEXT(B26,"aaa") -> 火 | T26: =SUM(D26:S26) -> 0 | V26: 0.375 | W26: 0.72916667 | X26: 0.052083333 | Y26: =(W26-V26-X26)*24 -> 7.25 | Z26: =Y26-T26 -> 7.25 | AA26: =AC26-AB26 -> 0 | AB26: 7.25 | AC26: =ABS(Y26) -> 7.25
B27: 46225 | C27: =TEXT(B27,"aaa") -> 水 | T27: =SUM(D27:S27) -> 0 | V27: 0.375 | W27: 0.72916667 | X27: 0.052083333 | Y27: =(W27-V27-X27)*24 -> 7.25 | Z27: =Y27-T27 -> 7.25 | AA27: =AC27-AB27 -> 0 | AB27: 7.25 | AC27: =ABS(Y27) -> 7.25
B28: 46226 | C28: =TEXT(B28,"aaa") -> 木 | T28: =SUM(D28:S28) -> 0 | V28: 0.375 | W28: 0.72916667 | X28: 0.052083333 | Y28: =(W28-V28-X28)*24 -> 7.25 | Z28: =Y28-T28 -> 7.25 | AA28: =AC28-AB28 -> 0 | AB28: 7.25 | AC28: =ABS(Y28) -> 7.25
B29: 46227 | C29: =TEXT(B29,"aaa") -> 金 | T29: =SUM(D29:S29) -> 0 | V29: 0.375 | W29: 0.72916667 | X29: 0.052083333 | Y29: =(W29-V29-X29)*24 -> 7.25 | Z29: =Y29-T29 -> 7.25 | AA29: =AC29-AB29 -> 0 | AB29: 7.25 | AC29: =ABS(Y29) -> 7.25
B30: 46228 | C30: =TEXT(B30,"aaa") -> 土 | T30: =SUM(D30:S30) -> 0 | Y30: =(W30-V30-X30)*24 -> 0 | Z30: =Y30-T30 -> 0
B31: 46229 | C31: =TEXT(B31,"aaa") -> 日 | T31: =SUM(D31:S31) -> 0 | Y31: =(W31-V31-X31)*24 -> 0 | Z31: =Y31-T31 -> 0
B32: 46230 | C32: =TEXT(B32,"aaa") -> 月 | T32: =SUM(D32:S32) -> 0 | V32: 0.375 | W32: 0.72916667 | X32: 0.052083333 | Y32: =(W32-V32-X32)*24 -> 7.25 | Z32: =Y32-T32 -> 7.25 | AA32: =AC32-AB32 -> 0 | AB32: 7.25 | AC32: =ABS(Y32) -> 7.25
B33: 46231 | C33: =TEXT(B33,"aaa") -> 火 | T33: =SUM(D33:S33) -> 0 | V33: 0.375 | W33: 0.72916667 | X33: 0.052083333 | Y33: =(W33-V33-X33)*24 -> 7.25 | Z33: =Y33-T33 -> 7.25 | AA33: =AC33-AB33 -> 0 | AB33: 7.25 | AC33: =ABS(Y33) -> 7.25
B34: 46232 | C34: =TEXT(B34,"aaa") -> 水 | T34: =SUM(D34:S34) -> 0 | V34: 0.375 | W34: 0.72916667 | X34: 0.052083333 | Y34: =(W34-V34-X34)*24 -> 7.25 | Z34: =Y34-T34 -> 7.25 | AA34: =AC34-AB34 -> 0 | AB34: 7.25 | AC34: =ABS(Y34) -> 7.25
B35: 46233 | C35: =TEXT(B35,"aaa") -> 木 | T35: =SUM(D35:S35) -> 0 | V35: 0.375 | W35: 0.72916667 | X35: 0.052083333 | Y35: =(W35-V35-X35)*24 -> 7.25 | Z35: =Y35-T35 -> 7.25 | AA35: =AC35-AB35 -> 0 | AB35: 7.25 | AC35: =ABS(Y35) -> 7.25
B36: 46234 | C36: =TEXT(B36,"aaa") -> 金 | T36: =SUM(D36:S36) -> 0 | V36: 0.375 | W36: 0.72916667 | X36: 0.052083333 | Y36: =(W36-V36-X36)*24 -> 7.25 | Z36: =Y36-T36 -> 7.25 | AA36: =AC36-AB36 -> 0 | AB36: 7.25 | AC36: =ABS(Y36) -> 7.25
B37: 月 | C37: 合計 | D37: =SUM(D6:D36) -> 0 | E37: =SUM(E6:E36) -> 0 | F37: =SUM(F6:F36) -> 0 | G37: =SUM(G6:G36) -> 0 | H37: =SUM(H6:H36) -> 0 | I37: =SUM(I6:I36) -> 0 | J37: =SUM(J6:J36) -> 0 | K37: =SUM(K6:K36) -> 0 | ... T37: =SUM(T6:T36) -> 0 | AA37: =SUM(AA6:AA36) -> 0 | AB37: =SUM(AB6:AB36) -> 159.5
B40: 直接経費（交通費等） | T40: 合計（円） | U40: 備考
C41: =TEXT(B41,"aaa") -> 土 | T41: =SUM(D41:S41) -> 0
C42: =TEXT(B42,"aaa") -> 土 | T42: =SUM(D42:S42) -> 0
C43: =TEXT(B43,"aaa") -> 土 | T43: =SUM(D43:S43) -> 0
...

Sheet 8月
B2: No. （件番SheetのNo.を入力⇒） | S2: 99
B3: 件番（自動入力） | D3: =IF(ISERROR(VLOOKUP(D2,件番!$A$10:$D$113,2,FALSE)),"",(VLOOKUP(D2,件番!$A$10:$D$113,2,FALSE))) | E3: =IF(ISERROR(VLOOKUP(E2,件番!$A$10:$D$113,2,FALSE)),"",(VLOOKUP(E2,件番!$A$10:$D$113,2,FALSE))) | F3: =IF(ISERROR(VLOOKUP(F2,件番!$A$10:$D$113,2,FALSE)),"",(VLOOKUP(F2,件番!$A$10:$D$113,2,FALSE))) | G3: =IF(ISERROR(VLOOKUP(G2,件番!$A$10:$D$113,2,FALSE)),"",(VLOOKUP(G2,件番!$A$10:$D$113,2,FALSE))) | H3: =IF(ISERROR(VLOOKUP(H2,件番!$A$10:$D$113,2,FALSE)),"",(VLOOKUP(H2,件番!$A$10:$D$113,2,FALSE))) | I3: =IF(ISERROR(VLOOKUP(I2,件番!$A$10:$D$113,2,FALSE)),"",(VLOOKUP(I2,件番!$A$10:$D$113,2,FALSE))) | J3: =IF(ISERROR(VLOOKUP(J2,件番!$A$10:$D$113,2,FALSE)),"",(VLOOKUP(J2,件番!$A$10:$D$113,2,FALSE))) | K3: =IF(ISERROR(VLOOKUP(K2,件番!$A$10:$D$113,2,FALSE)),"",(VLOOKUP(K2,件番!$A$10:$D$113,2,FALSE))) | ... O3: =IF(ISERROR(VLOOKUP(O2,件番!$A$10:$D$113,2,FALSE)),"",(VLOOKUP(O2,件番!$A$10:$D$113,2,FALSE))) | S3: =IF(ISERROR(VLOOKUP(S2,件番!$A$3:$D$113,2,FALSE)),"",(VLOOKUP(S2,件番!$A$3:$D$113,2,FALSE))) -> 2032B1008
B4: 件名（自動入力） | D4: =IF(ISERROR(VLOOKUP(D2,件番!$A$10:$D$113,2,FALSE)),"",(VLOOKUP(D2,件番!$A$10:$D$113,3,FALSE))) | E4: =IF(ISERROR(VLOOKUP(E2,件番!$A$10:$D$113,2,FALSE)),"",(VLOOKUP(E2,件番!$A$10:$D$113,3,FALSE))) | F4: =IF(ISERROR(VLOOKUP(F2,件番!$A$10:$D$113,2,FALSE)),"",(VLOOKUP(F2,件番!$A$10:$D$113,3,FALSE))) | G4: =IF(ISERROR(VLOOKUP(G2,件番!$A$10:$D$113,2,FALSE)),"",(VLOOKUP(G2,件番!$A$10:$D$113,3,FALSE))) | H4: =IF(ISERROR(VLOOKUP(H2,件番!$A$10:$D$113,2,FALSE)),"",(VLOOKUP(H2,件番!$A$10:$D$113,3,FALSE))) | I4: =IF(ISERROR(VLOOKUP(I2,件番!$A$10:$D$113,2,FALSE)),"",(VLOOKUP(I2,件番!$A$10:$D$113,3,FALSE))) | J4: =IF(ISERROR(VLOOKUP(J2,件番!$A$10:$D$113,2,FALSE)),"",(VLOOKUP(J2,件番!$A$10:$D$113,3,FALSE))) | K4: =IF(ISERROR(VLOOKUP(K2,件番!$A$10:$D$113,2,FALSE)),"",(VLOOKUP(K2,件番!$A$10:$D$113,3,FALSE))) | ... O4: =IF(ISERROR(VLOOKUP(O2,件番!$A$10:$D$113,2,FALSE)),"",(VLOOKUP(O2,件番!$A$10:$D$113,3,FALSE))) | S4: =IF(ISERROR(VLOOKUP(S2,件番!$A$3:$D$113,2,FALSE)),"",(VLOOKUP(S2,件番!$A$3:$D$113,3,FALSE))) -> 関東交通整備
B5: 管理（自動入力） | D5: =IF(ISERROR(VLOOKUP(D2,件番!$A$10:$D$113,2,FALSE)),"",(VLOOKUP(D2,件番!$A$10:$D$113,4,FALSE))) | E5: =IF(ISERROR(VLOOKUP(E2,件番!$A$10:$D$113,2,FALSE)),"",(VLOOKUP(E2,件番!$A$10:$D$113,4,FALSE))) | F5: =IF(ISERROR(VLOOKUP(F2,件番!$A$10:$D$113,2,FALSE)),"",(VLOOKUP(F2,件番!$A$10:$D$113,4,FALSE))) | G5: =IF(ISERROR(VLOOKUP(G2,件番!$A$10:$D$113,2,FALSE)),"",(VLOOKUP(G2,件番!$A$10:$D$113,4,FALSE))) | H5: =IF(ISERROR(VLOOKUP(H2,件番!$A$10:$D$113,2,FALSE)),"",(VLOOKUP(H2,件番!$A$10:$D$113,4,FALSE))) | I5: =IF(ISERROR(VLOOKUP(I2,件番!$A$10:$D$113,2,FALSE)),"",(VLOOKUP(I2,件番!$A$10:$D$113,4,FALSE))) | J5: =IF(ISERROR(VLOOKUP(J2,件番!$A$10:$D$113,2,FALSE)),"",(VLOOKUP(J2,件番!$A$10:$D$113,4,FALSE))) | K5: =IF(ISERROR(VLOOKUP(K2,件番!$A$10:$D$113,2,FALSE)),"",(VLOOKUP(K2,件番!$A$10:$D$113,4,FALSE))) | ... O5: =IF(ISERROR(VLOOKUP(O2,件番!$A$10:$D$113,2,FALSE)),"",(VLOOKUP(O2,件番!$A$10:$D$113,4,FALSE))) | S5: =IF(ISERROR(VLOOKUP(S2,件番!$A$3:$D$113,2,FALSE)),"",(VLOOKUP(S2,件番!$A$3:$D$113,4,FALSE))) -> 0 | T5: 合計 | U5: 備考 | V5: 始業 | W5: 終業 | X5: 休憩 | Y5: 就業時間 | Z5: チェック
B6: 46235 | C6: =TEXT(B6,"aaa") -> 土 | T6: =SUM(D6:S6) -> 0 | Y6: =(W6-V6-X6)*24 -> 0 | Z6: =Y6-T6 -> 0
B7: 46236 | C7: =TEXT(B7,"aaa") -> 日 | T7: =SUM(D7:S7) -> 0 | Y7: =(W7-V7-X7)*24 -> 0 | Z7: =Y7-T7 -> 0
B8: 46237 | C8: =TEXT(B8,"aaa") -> 月 | T8: =SUM(D8:S8) -> 0 | V8: 0.375 | W8: 0.72916667 | X8: 0.052083333 | Y8: =(W8-V8-X8)*24 -> 7.25 | Z8: =Y8-T8 -> 7.25 | AA8: =AC8-AB8 -> 0 | AB8: 7.25 | AC8: =ABS(Y8) -> 7.25
B9: 46238 | C9: =TEXT(B9,"aaa") -> 火 | T9: =SUM(D9:S9) -> 0 | V9: 0.375 | W9: 0.72916667 | X9: 0.052083333 | Y9: =(W9-V9-X9)*24 -> 7.25 | Z9: =Y9-T9 -> 7.25 | AA9: =AC9-AB9 -> 0 | AB9: 7.25 | AC9: =ABS(Y9) -> 7.25
B10: 46239 | C10: =TEXT(B10,"aaa") -> 水 | T10: =SUM(D10:S10) -> 0 | V10: 0.375 | W10: 0.72916667 | X10: 0.052083333 | Y10: =(W10-V10-X10)*24 -> 7.25 | Z10: =Y10-T10 -> 7.25 | AA10: =AC10-AB10 -> 0 | AB10: 7.25 | AC10: =ABS(Y10) -> 7.25
B11: 46240 | C11: =TEXT(B11,"aaa") -> 木 | T11: =SUM(D11:S11) -> 0 | V11: 0.375 | W11: 0.72916667 | X11: 0.052083333 | Y11: =(W11-V11-X11)*24 -> 7.25 | Z11: =Y11-T11 -> 7.25 | AA11: =AC11-AB11 -> 0 | AB11: 7.25 | AC11: =ABS(Y11) -> 7.25
B12: 46241 | C12: =TEXT(B12,"aaa") -> 金 | T12: =SUM(D12:S12) -> 0 | V12: 0.375 | W12: 0.72916667 | X12: 0.052083333 | Y12: =(W12-V12-X12)*24 -> 7.25 | Z12: =Y12-T12 -> 7.25 | AA12: =AC12-AB12 -> 0 | AB12: 7.25 | AC12: =ABS(Y12) -> 7.25
B13: 46242 | C13: =TEXT(B13,"aaa") -> 土 | T13: =SUM(D13:S13) -> 0 | Y13: =(W13-V13-X13)*24 -> 0 | Z13: =Y13-T13 -> 0
B14: 46243 | C14: =TEXT(B14,"aaa") -> 日 | T14: =SUM(D14:S14) -> 0 | Y14: =(W14-V14-X14)*24 -> 0 | Z14: =Y14-T14 -> 0
B15: 46244 | C15: =TEXT(B15,"aaa") -> 月 | T15: =SUM(D15:S15) -> 0 | V15: 0.375 | W15: 0.72916667 | X15: 0.052083333 | Y15: =(W15-V15-X15)*24 -> 7.25 | Z15: =Y15-T15 -> 7.25 | AA15: =AC15-AB15 -> 0 | AB15: 7.25 | AC15: =ABS(Y15) -> 7.25
B16: 46245 | C16: =TEXT(B16,"aaa") -> 火 | T16: =SUM(D16:S16) -> 0 | U16: 山の日 | Y16: =(W16-V16-X16)*24 -> 0 | Z16: =Y16-T16 -> 0
B17: 46246 | C17: =TEXT(B17,"aaa") -> 水 | T17: =SUM(D17:S17) -> 0 | V17: 0.375 | W17: 0.72916667 | X17: 0.052083333 | Y17: =(W17-V17-X17)*24 -> 7.25 | Z17: =Y17-T17 -> 7.25 | AA17: =AC17-AB17 -> 0 | AB17: 7.25 | AC17: =ABS(Y17) -> 7.25
B18: 46247 | C18: =TEXT(B18,"aaa") -> 木 | T18: =SUM(D18:S18) -> 0 | V18: 0.375 | W18: 0.72916667 | X18: 0.052083333 | Y18: =(W18-V18-X18)*24 -> 7.25 | Z18: =Y18-T18 -> 7.25 | AA18: =AC18-AB18 -> 0 | AB18: 7.25 | AC18: =ABS(Y18) -> 7.25
B19: 46248 | C19: =TEXT(B19,"aaa") -> 金 | T19: =SUM(D19:S19) -> 0 | V19: 0.375 | W19: 0.72916667 | X19: 0.052083333 | Y19: =(W19-V19-X19)*24 -> 7.25 | Z19: =Y19-T19 -> 7.25 | AA19: =AC19-AB19 -> 0 | AB19: 7.25 | AC19: =ABS(Y19) -> 7.25
B20: 46249 | C20: =TEXT(B20,"aaa") -> 土 | T20: =SUM(D20:S20) -> 0 | Y20: =(W20-V20-X20)*24 -> 0 | Z20: =Y20-T20 -> 0
B21: 46250 | C21: =TEXT(B21,"aaa") -> 日 | T21: =SUM(D21:S21) -> 0 | Y21: =(W21-V21-X21)*24 -> 0 | Z21: =Y21-T21 -> 0
B22: 46251 | C22: =TEXT(B22,"aaa") -> 月 | T22: =SUM(D22:S22) -> 0 | V22: 0.375 | W22: 0.72916667 | X22: 0.052083333 | Y22: =(W22-V22-X22)*24 -> 7.25 | Z22: =Y22-T22 -> 7.25 | AA22: =AC22-AB22 -> 0 | AB22: 7.25 | AC22: =ABS(Y22) -> 7.25
B23: 46252 | C23: =TEXT(B23,"aaa") -> 火 | T23: =SUM(D23:S23) -> 0 | V23: 0.375 | W23: 0.72916667 | X23: 0.052083333 | Y23: =(W23-V23-X23)*24 -> 7.25 | Z23: =Y23-T23 -> 7.25 | AA23: =AC23-AB23 -> 0 | AB23: 7.25 | AC23: =ABS(Y23) -> 7.25
B24: 46253 | C24: =TEXT(B24,"aaa") -> 水 | T24: =SUM(D24:S24) -> 0 | V24: 0.375 | W24: 0.72916667 | X24: 0.052083333 | Y24: =(W24-V24-X24)*24 -> 7.25 | Z24: =Y24-T24 -> 7.25 | AA24: =AC24-AB24 -> 0 | AB24: 7.25 | AC24: =ABS(Y24) -> 7.25
B25: 46254 | C25: =TEXT(B25,"aaa") -> 木 | T25: =SUM(D25:S25) -> 0 | V25: 0.375 | W25: 0.72916667 | X25: 0.052083333 | Y25: =(W25-V25-X25)*24 -> 7.25 | Z25: =Y25-T25 -> 7.25 | AA25: =AC25-AB25 -> 0 | AB25: 7.25 | AC25: =ABS(Y25) -> 7.25
B26: 46255 | C26: =TEXT(B26,"aaa") -> 金 | T26: =SUM(D26:S26) -> 0 | V26: 0.375 | W26: 0.72916667 | X26: 0.052083333 | Y26: =(W26-V26-X26)*24 -> 7.25 | Z26: =Y26-T26 -> 7.25 | AA26: =AC26-AB26 -> 0 | AB26: 7.25 | AC26: =ABS(Y26) -> 7.25
B27: 46256 | C27: =TEXT(B27,"aaa") -> 土 | T27: =SUM(D27:S27) -> 0 | Y27: =(W27-V27-X27)*24 -> 0 | Z27: =Y27-T27 -> 0
B28: 46257 | C28: =TEXT(B28,"aaa") -> 日 | T28: =SUM(D28:S28) -> 0 | Y28: =(W28-V28-X28)*24 -> 0 | Z28: =Y28-T28 -> 0
B29: 46258 | C29: =TEXT(B29,"aaa") -> 月 | T29: =SUM(D29:S29) -> 0 | V29: 0.375 | W29: 0.72916667 | X29: 0.052083333 | Y29: =(W29-V29-X29)*24 -> 7.25 | Z29: =Y29-T29 -> 7.25 | AA29: =AC29-AB29 -> 0 | AB29: 7.25 | AC29: =ABS(Y29) -> 7.25
B30: 46259 | C30: =TEXT(B30,"aaa") -> 火 | T30: =SUM(D30:S30) -> 0 | V30: 0.375 | W30: 0.72916667 | X30: 0.052083333 | Y30: =(W30-V30-X30)*24 -> 7.25 | Z30: =Y30-T30 -> 7.25 | AA30: =AC30-AB30 -> 0 | AB30: 7.25 | AC30: =ABS(Y30) -> 7.25
B31: 46260 | C31: =TEXT(B31,"aaa") -> 水 | T31: =SUM(D31:S31) -> 0 | V31: 0.375 | W31: 0.72916667 | X31: 0.052083333 | Y31: =(W31-V31-X31)*24 -> 7.25 | Z31: =Y31-T31 -> 7.25 | AA31: =AC31-AB31 -> 0 | AB31: 7.25 | AC31: =ABS(Y31) -> 7.25
B32: 46261 | C32: =TEXT(B32,"aaa") -> 木 | T32: =SUM(D32:S32) -> 0 | V32: 0.375 | W32: 0.72916667 | X32: 0.052083333 | Y32: =(W32-V32-X32)*24 -> 7.25 | Z32: =Y32-T32 -> 7.25 | AA32: =AC32-AB32 -> 0 | AB32: 7.25 | AC32: =ABS(Y32) -> 7.25
B33: 46262 | C33: =TEXT(B33,"aaa") -> 金 | T33: =SUM(D33:S33) -> 0 | V33: 0.375 | W33: 0.72916667 | X33: 0.052083333 | Y33: =(W33-V33-X33)*24 -> 7.25 | Z33: =Y33-T33 -> 7.25 | AA33: =AC33-AB33 -> 0 | AB33: 7.25 | AC33: =ABS(Y33) -> 7.25
B34: 46263 | C34: =TEXT(B34,"aaa") -> 土 | T34: =SUM(D34:S34) -> 0 | Y34: =(W34-V34-X34)*24 -> 0 | Z34: =Y34-T34 -> 0
B35: 46264 | C35: =TEXT(B35,"aaa") -> 日 | T35: =SUM(D35:S35) -> 0 | Y35: =(W35-V35-X35)*24 -> 0 | Z35: =Y35-T35 -> 0
B36: 46265 | C36: =TEXT(B36,"aaa") -> 月 | T36: =SUM(D36:S36) -> 0 | V36: 0.375 | W36: 0.72916667 | X36: 0.052083333 | Y36: =(W36-V36-X36)*24 -> 7.25 | Z36: =Y36-T36 -> 7.25 | AA36: =AC36-AB36 -> 0 | AB36: 7.25 | AC36: =ABS(Y36) -> 7.25
